/bin/sh: md5: command not found
/bin/sh: md5: command not found
/bin/sh: md5: command not found
/bin/sh: md5: command not found
To git@github.com:dajun928/Tool.git
   ac0407f..a4db942  master -> master
/bin/sh: md5: command not found
/bin/sh: md5: command not found
/bin/sh: md5: command not found
/bin/sh: md5: command not found
To git@github.com:dajun928/Tool.git
   a4db942..a88dacc  master -> master
To git@github.com:dajun928/Tool.git
   bcf59b8..c3fa545  master -> master
To git@github.com:dajun928/Tool.git
   b6ecf08..c760506  master -> master
To git@github.com:dajun928/Tool.git
   87f988b..12feef2  master -> master
To git@github.com:dajun928/Tool.git
   df4c3c0..961ee47  master -> master
To git@github.com:dajun928/Tool.git
   961ee47..e261915  master -> master
To git@github.com:dajun928/Tool.git
   e261915..b201ff0  master -> master
To git@github.com:dajun928/Tool.git
   b201ff0..f820415  master -> master
To git@github.com:dajun928/Tool.git
   f820415..aa69824  master -> master
To git@github.com:dajun928/Tool.git
   aa69824..ee374c7  master -> master
To git@github.com:dajun928/Tool.git
   ee374c7..24f6186  master -> master
Received disconnect from 13.250.177.223 port 22:11: Bye Bye
Authentication failed.
fatal: Could not read from remote repository.

Please make sure you have the correct access rights
and the repository exists.
To git@github.com:dajun928/Tool.git
   24f6186..bd81b63  master -> master
To git@github.com:dajun928/Tool.git
   bd81b63..acae34f  master -> master
To git@github.com:dajun928/Tool.git
   acae34f..a6adc86  master -> master
To git@github.com:dajun928/Tool.git
   a6adc86..db4630a  master -> master
To git@github.com:dajun928/Tool.git
   db4630a..f223c08  master -> master
To git@github.com:dajun928/Tool.git
   f223c08..76d629f  master -> master
To git@github.com:dajun928/Tool.git
   76d629f..a260d44  master -> master
To git@github.com:dajun928/Tool.git
   a260d44..2755eb2  master -> master
To git@github.com:dajun928/Tool.git
   2755eb2..6603be4  master -> master
To git@github.com:dajun928/Tool.git
   6603be4..d374e9a  master -> master
To git@github.com:dajun928/Tool.git
   d374e9a..43cafba  master -> master
To git@github.com:dajun928/Tool.git
   43cafba..2c741a0  master -> master
To git@github.com:dajun928/Tool.git
   2c741a0..cb3691f  master -> master
To git@github.com:dajun928/Tool.git
   cb3691f..0dc2ab5  master -> master
To git@github.com:dajun928/Tool.git
   0dc2ab5..255e512  master -> master
To git@github.com:dajun928/Tool.git
   255e512..4cb3743  master -> master
To git@github.com:dajun928/Tool.git
   4cb3743..50fe825  master -> master
To git@github.com:dajun928/Tool.git
   50fe825..4fa0a8c  master -> master
To git@github.com:dajun928/Tool.git
   4fa0a8c..e62f29e  master -> master
To git@github.com:dajun928/Tool.git
   e62f29e..9efc292  master -> master
To git@github.com:dajun928/Tool.git
   9efc292..5c79f3c  master -> master
To git@github.com:dajun928/Tool.git
   5c79f3c..36a46e1  master -> master
To git@github.com:dajun928/Tool.git
   36a46e1..e086444  master -> master
To git@github.com:dajun928/Tool.git
   e086444..f215be4  master -> master
Job "cut_single_file (trigger: cron[hour='23', minute='22'], next run at: 2019-05-23 23:22:00 CST)" raised an exception
Traceback (most recent call last):
  File "/root/anaconda3/lib/python3.6/site-packages/apscheduler/executors/base.py", line 125, in run_job
    retval = job.func(*job.args, **job.kwargs)
  File "control.py", line 56, in cut_single_file
    shutil.move(src_file, dsc_path)
  File "/root/anaconda3/lib/python3.6/shutil.py", line 542, in move
    raise Error("Destination path '%s' already exists" % real_dst)
shutil.Error: Destination path '/root/Projects/gitdemo/test/Tool/Tool/README.md' already exists
To git@github.com:dajun928/Tool.git
   f215be4..5656cfd  master -> master
Job "cut_single_file (trigger: cron[hour='23', minute='22'], next run at: 2019-05-24 23:22:00 CST)" raised an exception
Traceback (most recent call last):
  File "/root/anaconda3/lib/python3.6/site-packages/apscheduler/executors/base.py", line 125, in run_job
    retval = job.func(*job.args, **job.kwargs)
  File "control.py", line 56, in cut_single_file
    shutil.move(src_file, dsc_path)
  File "/root/anaconda3/lib/python3.6/shutil.py", line 542, in move
    raise Error("Destination path '%s' already exists" % real_dst)
shutil.Error: Destination path '/root/Projects/gitdemo/test/Tool/Tool/README.md' already exists
To git@github.com:dajun928/Tool.git
   5656cfd..1e545a6  master -> master
Job "cut_single_file (trigger: cron[hour='23', minute='22'], next run at: 2019-05-25 23:22:00 CST)" raised an exception
Traceback (most recent call last):
  File "/root/anaconda3/lib/python3.6/site-packages/apscheduler/executors/base.py", line 125, in run_job
    retval = job.func(*job.args, **job.kwargs)
  File "control.py", line 56, in cut_single_file
    shutil.move(src_file, dsc_path)
  File "/root/anaconda3/lib/python3.6/shutil.py", line 542, in move
    raise Error("Destination path '%s' already exists" % real_dst)
shutil.Error: Destination path '/root/Projects/gitdemo/test/Tool/Tool/README.md' already exists
To git@github.com:dajun928/Tool.git
   1e545a6..9325a24  master -> master
Job "cut_single_file (trigger: cron[hour='23', minute='22'], next run at: 2019-05-26 23:22:00 CST)" raised an exception
Traceback (most recent call last):
  File "/root/anaconda3/lib/python3.6/site-packages/apscheduler/executors/base.py", line 125, in run_job
    retval = job.func(*job.args, **job.kwargs)
  File "control.py", line 56, in cut_single_file
    shutil.move(src_file, dsc_path)
  File "/root/anaconda3/lib/python3.6/shutil.py", line 542, in move
    raise Error("Destination path '%s' already exists" % real_dst)
shutil.Error: Destination path '/root/Projects/gitdemo/test/Tool/Tool/README.md' already exists
To git@github.com:dajun928/Tool.git
   9325a24..e97a6b1  master -> master
Job "cut_single_file (trigger: cron[hour='23', minute='22'], next run at: 2019-05-27 23:22:00 CST)" raised an exception
Traceback (most recent call last):
  File "/root/anaconda3/lib/python3.6/site-packages/apscheduler/executors/base.py", line 125, in run_job
    retval = job.func(*job.args, **job.kwargs)
  File "control.py", line 56, in cut_single_file
    shutil.move(src_file, dsc_path)
  File "/root/anaconda3/lib/python3.6/shutil.py", line 542, in move
    raise Error("Destination path '%s' already exists" % real_dst)
shutil.Error: Destination path '/root/Projects/gitdemo/test/Tool/Tool/README.md' already exists
To git@github.com:dajun928/Tool.git
   e97a6b1..c697951  master -> master
Job "cut_single_file (trigger: cron[hour='23', minute='22'], next run at: 2019-05-28 23:22:00 CST)" raised an exception
Traceback (most recent call last):
  File "/root/anaconda3/lib/python3.6/site-packages/apscheduler/executors/base.py", line 125, in run_job
    retval = job.func(*job.args, **job.kwargs)
  File "control.py", line 56, in cut_single_file
    shutil.move(src_file, dsc_path)
  File "/root/anaconda3/lib/python3.6/shutil.py", line 542, in move
    raise Error("Destination path '%s' already exists" % real_dst)
shutil.Error: Destination path '/root/Projects/gitdemo/test/Tool/Tool/README.md' already exists
ERROR: You must verify your email address.
See https://github.com/settings/emails.

fatal: Could not read from remote repository.

Please make sure you have the correct access rights
and the repository exists.
Job "cut_single_file (trigger: cron[hour='23', minute='22'], next run at: 2019-05-29 23:22:00 CST)" raised an exception
Traceback (most recent call last):
  File "/root/anaconda3/lib/python3.6/site-packages/apscheduler/executors/base.py", line 125, in run_job
    retval = job.func(*job.args, **job.kwargs)
  File "control.py", line 56, in cut_single_file
    shutil.move(src_file, dsc_path)
  File "/root/anaconda3/lib/python3.6/shutil.py", line 542, in move
    raise Error("Destination path '%s' already exists" % real_dst)
shutil.Error: Destination path '/root/Projects/gitdemo/test/Tool/Tool/README.md' already exists
ERROR: You must verify your email address.
See https://github.com/settings/emails.

fatal: Could not read from remote repository.

Please make sure you have the correct access rights
and the repository exists.
Job "cut_single_file (trigger: cron[hour='23', minute='22'], next run at: 2019-05-30 23:22:00 CST)" raised an exception
Traceback (most recent call last):
  File "/root/anaconda3/lib/python3.6/site-packages/apscheduler/executors/base.py", line 125, in run_job
    retval = job.func(*job.args, **job.kwargs)
  File "control.py", line 56, in cut_single_file
    shutil.move(src_file, dsc_path)
  File "/root/anaconda3/lib/python3.6/shutil.py", line 542, in move
    raise Error("Destination path '%s' already exists" % real_dst)
shutil.Error: Destination path '/root/Projects/gitdemo/test/Tool/Tool/README.md' already exists
ERROR: You must verify your email address.
See https://github.com/settings/emails.

fatal: Could not read from remote repository.

Please make sure you have the correct access rights
and the repository exists.
Job "cut_single_file (trigger: cron[hour='23', minute='22'], next run at: 2019-05-31 23:22:00 CST)" raised an exception
Traceback (most recent call last):
  File "/root/anaconda3/lib/python3.6/site-packages/apscheduler/executors/base.py", line 125, in run_job
    retval = job.func(*job.args, **job.kwargs)
  File "control.py", line 56, in cut_single_file
    shutil.move(src_file, dsc_path)
  File "/root/anaconda3/lib/python3.6/shutil.py", line 542, in move
    raise Error("Destination path '%s' already exists" % real_dst)
shutil.Error: Destination path '/root/Projects/gitdemo/test/Tool/Tool/README.md' already exists
ERROR: You must verify your email address.
See https://github.com/settings/emails.

fatal: Could not read from remote repository.

Please make sure you have the correct access rights
and the repository exists.
Job "cut_single_file (trigger: cron[hour='23', minute='22'], next run at: 2019-06-01 23:22:00 CST)" raised an exception
Traceback (most recent call last):
  File "/root/anaconda3/lib/python3.6/site-packages/apscheduler/executors/base.py", line 125, in run_job
    retval = job.func(*job.args, **job.kwargs)
  File "control.py", line 56, in cut_single_file
    shutil.move(src_file, dsc_path)
  File "/root/anaconda3/lib/python3.6/shutil.py", line 542, in move
    raise Error("Destination path '%s' already exists" % real_dst)
shutil.Error: Destination path '/root/Projects/gitdemo/test/Tool/Tool/README.md' already exists
ERROR: You must verify your email address.
See https://github.com/settings/emails.

fatal: Could not read from remote repository.

Please make sure you have the correct access rights
and the repository exists.
Job "cut_single_file (trigger: cron[hour='23', minute='22'], next run at: 2019-06-02 23:22:00 CST)" raised an exception
Traceback (most recent call last):
  File "/root/anaconda3/lib/python3.6/site-packages/apscheduler/executors/base.py", line 125, in run_job
    retval = job.func(*job.args, **job.kwargs)
  File "control.py", line 56, in cut_single_file
    shutil.move(src_file, dsc_path)
  File "/root/anaconda3/lib/python3.6/shutil.py", line 542, in move
    raise Error("Destination path '%s' already exists" % real_dst)
shutil.Error: Destination path '/root/Projects/gitdemo/test/Tool/Tool/README.md' already exists
ERROR: You must verify your email address.
See https://github.com/settings/emails.

fatal: Could not read from remote repository.

Please make sure you have the correct access rights
and the repository exists.
Job "cut_single_file (trigger: cron[hour='23', minute='22'], next run at: 2019-06-03 23:22:00 CST)" raised an exception
Traceback (most recent call last):
  File "/root/anaconda3/lib/python3.6/site-packages/apscheduler/executors/base.py", line 125, in run_job
    retval = job.func(*job.args, **job.kwargs)
  File "control.py", line 56, in cut_single_file
    shutil.move(src_file, dsc_path)
  File "/root/anaconda3/lib/python3.6/shutil.py", line 542, in move
    raise Error("Destination path '%s' already exists" % real_dst)
shutil.Error: Destination path '/root/Projects/gitdemo/test/Tool/Tool/README.md' already exists
To git@github.com:dajun928/Tool.git
   de27e06..e17873b  master -> master
Job "cut_single_file (trigger: cron[hour='23', minute='22'], next run at: 2019-06-04 23:22:00 CST)" raised an exception
Traceback (most recent call last):
  File "/root/anaconda3/lib/python3.6/site-packages/apscheduler/executors/base.py", line 125, in run_job
    retval = job.func(*job.args, **job.kwargs)
  File "control.py", line 56, in cut_single_file
    shutil.move(src_file, dsc_path)
  File "/root/anaconda3/lib/python3.6/shutil.py", line 542, in move
    raise Error("Destination path '%s' already exists" % real_dst)
shutil.Error: Destination path '/root/Projects/gitdemo/test/Tool/Tool/README.md' already exists
ERROR: You must verify your email address.
See https://github.com/settings/emails.

fatal: Could not read from remote repository.

Please make sure you have the correct access rights
and the repository exists.
Job "cut_single_file (trigger: cron[hour='23', minute='22'], next run at: 2019-06-05 23:22:00 CST)" raised an exception
Traceback (most recent call last):
  File "/root/anaconda3/lib/python3.6/site-packages/apscheduler/executors/base.py", line 125, in run_job
    retval = job.func(*job.args, **job.kwargs)
  File "control.py", line 56, in cut_single_file
    shutil.move(src_file, dsc_path)
  File "/root/anaconda3/lib/python3.6/shutil.py", line 542, in move
    raise Error("Destination path '%s' already exists" % real_dst)
shutil.Error: Destination path '/root/Projects/gitdemo/test/Tool/Tool/README.md' already exists
To git@github.com:dajun928/Tool.git
   97e1173..8768b1b  master -> master
Job "cut_single_file (trigger: cron[hour='23', minute='22'], next run at: 2019-06-06 23:22:00 CST)" raised an exception
Traceback (most recent call last):
  File "/root/anaconda3/lib/python3.6/site-packages/apscheduler/executors/base.py", line 125, in run_job
    retval = job.func(*job.args, **job.kwargs)
  File "control.py", line 56, in cut_single_file
    shutil.move(src_file, dsc_path)
  File "/root/anaconda3/lib/python3.6/shutil.py", line 542, in move
    raise Error("Destination path '%s' already exists" % real_dst)
shutil.Error: Destination path '/root/Projects/gitdemo/test/Tool/Tool/README.md' already exists
ERROR: You must verify your email address.
See https://github.com/settings/emails.

fatal: Could not read from remote repository.

Please make sure you have the correct access rights
and the repository exists.
Job "cut_single_file (trigger: cron[hour='23', minute='22'], next run at: 2019-06-07 23:22:00 CST)" raised an exception
Traceback (most recent call last):
  File "/root/anaconda3/lib/python3.6/site-packages/apscheduler/executors/base.py", line 125, in run_job
    retval = job.func(*job.args, **job.kwargs)
  File "control.py", line 56, in cut_single_file
    shutil.move(src_file, dsc_path)
  File "/root/anaconda3/lib/python3.6/shutil.py", line 542, in move
    raise Error("Destination path '%s' already exists" % real_dst)
shutil.Error: Destination path '/root/Projects/gitdemo/test/Tool/Tool/README.md' already exists
ERROR: You must verify your email address.
See https://github.com/settings/emails.

fatal: Could not read from remote repository.

Please make sure you have the correct access rights
and the repository exists.
Job "cut_single_file (trigger: cron[hour='23', minute='22'], next run at: 2019-06-08 23:22:00 CST)" raised an exception
Traceback (most recent call last):
  File "/root/anaconda3/lib/python3.6/site-packages/apscheduler/executors/base.py", line 125, in run_job
    retval = job.func(*job.args, **job.kwargs)
  File "control.py", line 56, in cut_single_file
    shutil.move(src_file, dsc_path)
  File "/root/anaconda3/lib/python3.6/shutil.py", line 542, in move
    raise Error("Destination path '%s' already exists" % real_dst)
shutil.Error: Destination path '/root/Projects/gitdemo/test/Tool/Tool/README.md' already exists
ERROR: You must verify your email address.
See https://github.com/settings/emails.

fatal: Could not read from remote repository.

Please make sure you have the correct access rights
and the repository exists.
Job "cut_single_file (trigger: cron[hour='23', minute='22'], next run at: 2019-06-09 23:22:00 CST)" raised an exception
Traceback (most recent call last):
  File "/root/anaconda3/lib/python3.6/site-packages/apscheduler/executors/base.py", line 125, in run_job
    retval = job.func(*job.args, **job.kwargs)
  File "control.py", line 56, in cut_single_file
    shutil.move(src_file, dsc_path)
  File "/root/anaconda3/lib/python3.6/shutil.py", line 542, in move
    raise Error("Destination path '%s' already exists" % real_dst)
shutil.Error: Destination path '/root/Projects/gitdemo/test/Tool/Tool/README.md' already exists
ERROR: You must verify your email address.
See https://github.com/settings/emails.

fatal: Could not read from remote repository.

Please make sure you have the correct access rights
and the repository exists.
Job "cut_single_file (trigger: cron[hour='23', minute='22'], next run at: 2019-06-10 23:22:00 CST)" raised an exception
Traceback (most recent call last):
  File "/root/anaconda3/lib/python3.6/site-packages/apscheduler/executors/base.py", line 125, in run_job
    retval = job.func(*job.args, **job.kwargs)
  File "control.py", line 56, in cut_single_file
    shutil.move(src_file, dsc_path)
  File "/root/anaconda3/lib/python3.6/shutil.py", line 542, in move
    raise Error("Destination path '%s' already exists" % real_dst)
shutil.Error: Destination path '/root/Projects/gitdemo/test/Tool/Tool/README.md' already exists
To git@github.com:dajun928/Tool.git
   580ff0d..dcf65b6  master -> master
Job "cut_single_file (trigger: cron[hour='23', minute='22'], next run at: 2019-06-11 23:22:00 CST)" raised an exception
Traceback (most recent call last):
  File "/root/anaconda3/lib/python3.6/site-packages/apscheduler/executors/base.py", line 125, in run_job
    retval = job.func(*job.args, **job.kwargs)
  File "control.py", line 56, in cut_single_file
    shutil.move(src_file, dsc_path)
  File "/root/anaconda3/lib/python3.6/shutil.py", line 542, in move
    raise Error("Destination path '%s' already exists" % real_dst)
shutil.Error: Destination path '/root/Projects/gitdemo/test/Tool/Tool/README.md' already exists
To git@github.com:dajun928/Tool.git
   dcf65b6..b08c69b  master -> master
Job "cut_single_file (trigger: cron[hour='23', minute='22'], next run at: 2019-06-12 23:22:00 CST)" raised an exception
Traceback (most recent call last):
  File "/root/anaconda3/lib/python3.6/site-packages/apscheduler/executors/base.py", line 125, in run_job
    retval = job.func(*job.args, **job.kwargs)
  File "control.py", line 56, in cut_single_file
    shutil.move(src_file, dsc_path)
  File "/root/anaconda3/lib/python3.6/shutil.py", line 542, in move
    raise Error("Destination path '%s' already exists" % real_dst)
shutil.Error: Destination path '/root/Projects/gitdemo/test/Tool/Tool/README.md' already exists
To git@github.com:dajun928/Tool.git
   b08c69b..62beb3b  master -> master
To git@github.com:dajun928/Tool.git
   62beb3b..8b823d2  master -> master
To git@github.com:dajun928/Tool.git
   8b823d2..bd9048f  master -> master
Job "cut_single_file (trigger: cron[hour='23', minute='22'], next run at: 2019-06-15 23:22:00 CST)" raised an exception
Traceback (most recent call last):
  File "/root/anaconda3/lib/python3.6/site-packages/apscheduler/executors/base.py", line 125, in run_job
    retval = job.func(*job.args, **job.kwargs)
  File "control.py", line 56, in cut_single_file
    shutil.move(src_file, dsc_path)
  File "/root/anaconda3/lib/python3.6/shutil.py", line 542, in move
    raise Error("Destination path '%s' already exists" % real_dst)
shutil.Error: Destination path '/root/Projects/gitdemo/test/Tool/Tool/README.md' already exists
To git@github.com:dajun928/Tool.git
   bd9048f..2826ecd  master -> master
Job "cut_single_file (trigger: cron[hour='23', minute='22'], next run at: 2019-06-16 23:22:00 CST)" raised an exception
Traceback (most recent call last):
  File "/root/anaconda3/lib/python3.6/site-packages/apscheduler/executors/base.py", line 125, in run_job
    retval = job.func(*job.args, **job.kwargs)
  File "control.py", line 56, in cut_single_file
    shutil.move(src_file, dsc_path)
  File "/root/anaconda3/lib/python3.6/shutil.py", line 542, in move
    raise Error("Destination path '%s' already exists" % real_dst)
shutil.Error: Destination path '/root/Projects/gitdemo/test/Tool/Tool/README.md' already exists
To git@github.com:dajun928/Tool.git
   2826ecd..c281707  master -> master
Job "cut_single_file (trigger: cron[hour='23', minute='22'], next run at: 2019-06-17 23:22:00 CST)" raised an exception
Traceback (most recent call last):
  File "/root/anaconda3/lib/python3.6/site-packages/apscheduler/executors/base.py", line 125, in run_job
    retval = job.func(*job.args, **job.kwargs)
  File "control.py", line 56, in cut_single_file
    shutil.move(src_file, dsc_path)
  File "/root/anaconda3/lib/python3.6/shutil.py", line 542, in move
    raise Error("Destination path '%s' already exists" % real_dst)
shutil.Error: Destination path '/root/Projects/gitdemo/test/Tool/Tool/README.md' already exists
To git@github.com:dajun928/Tool.git
   c281707..6b9e32a  master -> master
Job "cut_single_file (trigger: cron[hour='23', minute='22'], next run at: 2019-06-18 23:22:00 CST)" raised an exception
Traceback (most recent call last):
  File "/root/anaconda3/lib/python3.6/site-packages/apscheduler/executors/base.py", line 125, in run_job
    retval = job.func(*job.args, **job.kwargs)
  File "control.py", line 56, in cut_single_file
    shutil.move(src_file, dsc_path)
  File "/root/anaconda3/lib/python3.6/shutil.py", line 542, in move
    raise Error("Destination path '%s' already exists" % real_dst)
shutil.Error: Destination path '/root/Projects/gitdemo/test/Tool/Tool/README.md' already exists
To git@github.com:dajun928/Tool.git
   6b9e32a..b77142c  master -> master
Job "cut_single_file (trigger: cron[hour='23', minute='22'], next run at: 2019-06-19 23:22:00 CST)" raised an exception
Traceback (most recent call last):
  File "/root/anaconda3/lib/python3.6/site-packages/apscheduler/executors/base.py", line 125, in run_job
    retval = job.func(*job.args, **job.kwargs)
  File "control.py", line 56, in cut_single_file
    shutil.move(src_file, dsc_path)
  File "/root/anaconda3/lib/python3.6/shutil.py", line 542, in move
    raise Error("Destination path '%s' already exists" % real_dst)
shutil.Error: Destination path '/root/Projects/gitdemo/test/Tool/Tool/README.md' already exists
To git@github.com:dajun928/Tool.git
   b77142c..f674a0c  master -> master
Job "cut_single_file (trigger: cron[hour='23', minute='22'], next run at: 2019-06-20 23:22:00 CST)" raised an exception
Traceback (most recent call last):
  File "/root/anaconda3/lib/python3.6/site-packages/apscheduler/executors/base.py", line 125, in run_job
    retval = job.func(*job.args, **job.kwargs)
  File "control.py", line 56, in cut_single_file
    shutil.move(src_file, dsc_path)
  File "/root/anaconda3/lib/python3.6/shutil.py", line 542, in move
    raise Error("Destination path '%s' already exists" % real_dst)
shutil.Error: Destination path '/root/Projects/gitdemo/test/Tool/Tool/README.md' already exists
To git@github.com:dajun928/Tool.git
   f674a0c..c3ddb35  master -> master
Job "cut_single_file (trigger: cron[hour='23', minute='22'], next run at: 2019-06-21 23:22:00 CST)" raised an exception
Traceback (most recent call last):
  File "/root/anaconda3/lib/python3.6/site-packages/apscheduler/executors/base.py", line 125, in run_job
    retval = job.func(*job.args, **job.kwargs)
  File "control.py", line 56, in cut_single_file
    shutil.move(src_file, dsc_path)
  File "/root/anaconda3/lib/python3.6/shutil.py", line 542, in move
    raise Error("Destination path '%s' already exists" % real_dst)
shutil.Error: Destination path '/root/Projects/gitdemo/test/Tool/Tool/README.md' already exists
To git@github.com:dajun928/Tool.git
   c3ddb35..4f7833b  master -> master
Job "cut_single_file (trigger: cron[hour='23', minute='22'], next run at: 2019-06-22 23:22:00 CST)" raised an exception
Traceback (most recent call last):
  File "/root/anaconda3/lib/python3.6/site-packages/apscheduler/executors/base.py", line 125, in run_job
    retval = job.func(*job.args, **job.kwargs)
  File "control.py", line 56, in cut_single_file
    shutil.move(src_file, dsc_path)
  File "/root/anaconda3/lib/python3.6/shutil.py", line 542, in move
    raise Error("Destination path '%s' already exists" % real_dst)
shutil.Error: Destination path '/root/Projects/gitdemo/test/Tool/Tool/README.md' already exists
To git@github.com:dajun928/Tool.git
   4f7833b..381038d  master -> master
Job "cut_single_file (trigger: cron[hour='23', minute='22'], next run at: 2019-06-23 23:22:00 CST)" raised an exception
Traceback (most recent call last):
  File "/root/anaconda3/lib/python3.6/site-packages/apscheduler/executors/base.py", line 125, in run_job
    retval = job.func(*job.args, **job.kwargs)
  File "control.py", line 56, in cut_single_file
    shutil.move(src_file, dsc_path)
  File "/root/anaconda3/lib/python3.6/shutil.py", line 542, in move
    raise Error("Destination path '%s' already exists" % real_dst)
shutil.Error: Destination path '/root/Projects/gitdemo/test/Tool/Tool/README.md' already exists
To git@github.com:dajun928/Tool.git
   381038d..1461eea  master -> master
Job "cut_single_file (trigger: cron[hour='23', minute='22'], next run at: 2019-06-24 23:22:00 CST)" raised an exception
Traceback (most recent call last):
  File "/root/anaconda3/lib/python3.6/site-packages/apscheduler/executors/base.py", line 125, in run_job
    retval = job.func(*job.args, **job.kwargs)
  File "control.py", line 56, in cut_single_file
    shutil.move(src_file, dsc_path)
  File "/root/anaconda3/lib/python3.6/shutil.py", line 542, in move
    raise Error("Destination path '%s' already exists" % real_dst)
shutil.Error: Destination path '/root/Projects/gitdemo/test/Tool/Tool/README.md' already exists
To git@github.com:dajun928/Tool.git
   a5ba647..a56df88  master -> master
Job "cut_single_file (trigger: cron[hour='23', minute='22'], next run at: 2019-06-25 23:22:00 CST)" raised an exception
Traceback (most recent call last):
  File "/root/anaconda3/lib/python3.6/site-packages/apscheduler/executors/base.py", line 125, in run_job
    retval = job.func(*job.args, **job.kwargs)
  File "control.py", line 56, in cut_single_file
    shutil.move(src_file, dsc_path)
  File "/root/anaconda3/lib/python3.6/shutil.py", line 542, in move
    raise Error("Destination path '%s' already exists" % real_dst)
shutil.Error: Destination path '/root/Projects/gitdemo/test/Tool/Tool/README.md' already exists
To git@github.com:dajun928/Tool.git
   a56df88..ab71182  master -> master
Job "cut_single_file (trigger: cron[hour='23', minute='22'], next run at: 2019-06-26 23:22:00 CST)" raised an exception
Traceback (most recent call last):
  File "/root/anaconda3/lib/python3.6/site-packages/apscheduler/executors/base.py", line 125, in run_job
    retval = job.func(*job.args, **job.kwargs)
  File "control.py", line 56, in cut_single_file
    shutil.move(src_file, dsc_path)
  File "/root/anaconda3/lib/python3.6/shutil.py", line 542, in move
    raise Error("Destination path '%s' already exists" % real_dst)
shutil.Error: Destination path '/root/Projects/gitdemo/test/Tool/Tool/README.md' already exists
To git@github.com:dajun928/Tool.git
   ab71182..fc026d7  master -> master
Job "cut_single_file (trigger: cron[hour='23', minute='22'], next run at: 2019-06-27 23:22:00 CST)" raised an exception
Traceback (most recent call last):
  File "/root/anaconda3/lib/python3.6/site-packages/apscheduler/executors/base.py", line 125, in run_job
    retval = job.func(*job.args, **job.kwargs)
  File "control.py", line 56, in cut_single_file
    shutil.move(src_file, dsc_path)
  File "/root/anaconda3/lib/python3.6/shutil.py", line 542, in move
    raise Error("Destination path '%s' already exists" % real_dst)
shutil.Error: Destination path '/root/Projects/gitdemo/test/Tool/Tool/README.md' already exists
To git@github.com:dajun928/Tool.git
   fc026d7..674212e  master -> master
Job "cut_single_file (trigger: cron[hour='23', minute='22'], next run at: 2019-06-28 23:22:00 CST)" raised an exception
Traceback (most recent call last):
  File "/root/anaconda3/lib/python3.6/site-packages/apscheduler/executors/base.py", line 125, in run_job
    retval = job.func(*job.args, **job.kwargs)
  File "control.py", line 56, in cut_single_file
    shutil.move(src_file, dsc_path)
  File "/root/anaconda3/lib/python3.6/shutil.py", line 542, in move
    raise Error("Destination path '%s' already exists" % real_dst)
shutil.Error: Destination path '/root/Projects/gitdemo/test/Tool/Tool/README.md' already exists
To git@github.com:dajun928/Tool.git
   674212e..5b86c05  master -> master
Job "cut_single_file (trigger: cron[hour='23', minute='22'], next run at: 2019-06-29 23:22:00 CST)" raised an exception
Traceback (most recent call last):
  File "/root/anaconda3/lib/python3.6/site-packages/apscheduler/executors/base.py", line 125, in run_job
    retval = job.func(*job.args, **job.kwargs)
  File "control.py", line 56, in cut_single_file
    shutil.move(src_file, dsc_path)
  File "/root/anaconda3/lib/python3.6/shutil.py", line 542, in move
    raise Error("Destination path '%s' already exists" % real_dst)
shutil.Error: Destination path '/root/Projects/gitdemo/test/Tool/Tool/README.md' already exists
To git@github.com:dajun928/Tool.git
   5b86c05..1e8c249  master -> master
Job "cut_single_file (trigger: cron[hour='23', minute='22'], next run at: 2019-06-30 23:22:00 CST)" raised an exception
Traceback (most recent call last):
  File "/root/anaconda3/lib/python3.6/site-packages/apscheduler/executors/base.py", line 125, in run_job
    retval = job.func(*job.args, **job.kwargs)
  File "control.py", line 56, in cut_single_file
    shutil.move(src_file, dsc_path)
  File "/root/anaconda3/lib/python3.6/shutil.py", line 542, in move
    raise Error("Destination path '%s' already exists" % real_dst)
shutil.Error: Destination path '/root/Projects/gitdemo/test/Tool/Tool/README.md' already exists
To git@github.com:dajun928/Tool.git
   1e8c249..2b9134c  master -> master
Job "cut_single_file (trigger: cron[hour='23', minute='22'], next run at: 2019-07-01 23:22:00 CST)" raised an exception
Traceback (most recent call last):
  File "/root/anaconda3/lib/python3.6/site-packages/apscheduler/executors/base.py", line 125, in run_job
    retval = job.func(*job.args, **job.kwargs)
  File "control.py", line 56, in cut_single_file
    shutil.move(src_file, dsc_path)
  File "/root/anaconda3/lib/python3.6/shutil.py", line 542, in move
    raise Error("Destination path '%s' already exists" % real_dst)
shutil.Error: Destination path '/root/Projects/gitdemo/test/Tool/Tool/README.md' already exists
To git@github.com:dajun928/Tool.git
   2b9134c..2387013  master -> master
Job "cut_single_file (trigger: cron[hour='23', minute='22'], next run at: 2019-07-02 23:22:00 CST)" raised an exception
Traceback (most recent call last):
  File "/root/anaconda3/lib/python3.6/site-packages/apscheduler/executors/base.py", line 125, in run_job
    retval = job.func(*job.args, **job.kwargs)
  File "control.py", line 56, in cut_single_file
    shutil.move(src_file, dsc_path)
  File "/root/anaconda3/lib/python3.6/shutil.py", line 542, in move
    raise Error("Destination path '%s' already exists" % real_dst)
shutil.Error: Destination path '/root/Projects/gitdemo/test/Tool/Tool/README.md' already exists
To git@github.com:dajun928/Tool.git
   2387013..0cc6fab  master -> master
To git@github.com:dajun928/Tool.git
   0cc6fab..351c6fd  master -> master
To git@github.com:dajun928/Tool.git
   351c6fd..566268b  master -> master
To git@github.com:dajun928/Tool.git
   566268b..bd12981  master -> master
To git@github.com:dajun928/Tool.git
   bd12981..101c349  master -> master
To git@github.com:dajun928/Tool.git
   101c349..70a5fff  master -> master
To git@github.com:dajun928/Tool.git
   70a5fff..539ca9d  master -> master
To git@github.com:dajun928/Tool.git
   539ca9d..8841d1f  master -> master
To git@github.com:dajun928/Tool.git
   8841d1f..5a3b2f0  master -> master
ssh: connect to host github.com port 22: Connection timed out
fatal: Could not read from remote repository.

Please make sure you have the correct access rights
and the repository exists.
To git@github.com:dajun928/Tool.git
   5a3b2f0..1117a05  master -> master
To git@github.com:dajun928/Tool.git
   1117a05..1379a67  master -> master
To git@github.com:dajun928/Tool.git
   1379a67..6e46330  master -> master
To git@github.com:dajun928/Tool.git
   6e46330..6029a0a  master -> master
To git@github.com:dajun928/Tool.git
   6029a0a..4025b74  master -> master
To git@github.com:dajun928/Tool.git
   4025b74..6457836  master -> master
To git@github.com:dajun928/Tool.git
   6457836..d69345e  master -> master
To git@github.com:dajun928/Tool.git
   d69345e..42b8568  master -> master
/root/homework/myTools/Del_Files.py
Tick! The time is: 2019-04-19 23:23:00.002854
/root/homework/myTools/TimeConvert.py
Tick! The time is: 2019-04-20 23:23:00.002778
/root/homework/myTools/Copy_Files.py
Tick! The time is: 2019-04-21 23:23:00.002909
/root/homework/myTools/MysqlHelper01.py
Tick! The time is: 2019-04-22 23:23:00.002861
/root/homework/myTools/__init__.py
Tick! The time is: 2019-04-23 23:23:00.003425
/root/homework/myTools/oracel_helper.py
Tick! The time is: 2019-04-24 23:23:00.001790
/root/homework/schedul/job.py
Tick! The time is: 2019-04-25 23:23:00.001913
/root/homework/redis/redislogin.py
Tick! The time is: 2019-04-26 23:23:00.002276
/root/homework/redis/testredis.py
Tick! The time is: 2019-04-27 23:23:00.002190
/root/homework/redis/RedisHelper.pyc
Tick! The time is: 2019-04-28 23:23:00.001847
/root/homework/redis/testredis03.py
Tick! The time is: 2019-04-29 23:23:00.001794
/root/homework/redis/testredis01.py
Tick! The time is: 2019-04-30 23:23:00.002297
/root/homework/redis/MessageProduce.py
Tick! The time is: 2019-05-01 23:23:00.002232
/root/homework/redis/MessageConsumer.py
Tick! The time is: 2019-05-02 23:23:00.002288
/root/homework/redis/testredis011.py
Tick! The time is: 2019-05-03 23:23:00.001717
/root/homework/redis/__init__.py
Tick! The time is: 2019-05-04 23:23:00.002257
/root/homework/redis/pipe01.py
Tick! The time is: 2019-05-05 23:23:00.001885
/root/homework/redis/testredis02.py
Tick! The time is: 2019-05-06 23:23:00.002065
/root/homework/redis/RedisHelper.py
Tick! The time is: 2019-05-07 23:23:00.002017
/root/homework/redis/testredis01.pyc
Tick! The time is: 2019-05-08 23:23:00.001929
/root/homework/mysql/autoquery.py
Tick! The time is: 2019-05-09 23:23:00.001958
/root/homework/mysql/testLogin.py
Tick! The time is: 2019-05-10 23:23:00.002405
/root/homework/mysql/autoinsert.py
Tick! The time is: 2019-05-11 23:23:00.001791
/root/homework/mysql/MysqlHelper.py
Tick! The time is: 2019-05-12 23:23:00.002024
/root/homework/mysql/MysqlHelper.pyc
Tick! The time is: 2019-05-13 23:23:00.001845
/root/homework/mysql/__init__.py
Tick! The time is: 2019-05-14 23:23:00.001992
/root/homework/mysql/testInsertWrap.py
Tick! The time is: 2019-05-15 23:23:00.001828
/root/homework/testQuery.py
Tick! The time is: 2019-05-16 23:23:00.001870
/root/homework/aaa.txt
Tick! The time is: 2019-05-17 23:23:00.002219
/root/homework/test01.sh
Tick! The time is: 2019-05-18 23:23:00.001853
/root/homework/test.log
Tick! The time is: 2019-05-19 23:23:00.001966
/root/homework/test.py
Tick! The time is: 2019-05-20 23:23:00.002184
/root/homework/testDelete.py
Tick! The time is: 2019-05-21 23:23:00.001978
/root/homework/README.md
Tick! The time is: 2019-05-22 23:23:00.001998
/root/homework/README.md
Tick! The time is: 2019-05-23 23:23:00.001922
/root/homework/README.md
Tick! The time is: 2019-05-24 23:23:00.001903
/root/homework/README.md
Tick! The time is: 2019-05-25 23:23:00.001920
/root/homework/README.md
Tick! The time is: 2019-05-26 23:23:00.001925
/root/homework/README.md
Tick! The time is: 2019-05-27 23:23:00.001950
/root/homework/README.md
Tick! The time is: 2019-05-28 23:23:00.001777
/root/homework/README.md
Tick! The time is: 2019-05-29 23:23:00.002326
/root/homework/README.md
Tick! The time is: 2019-05-30 23:23:00.001839
/root/homework/README.md
Tick! The time is: 2019-05-31 23:23:00.001833
/root/homework/README.md
Tick! The time is: 2019-06-01 23:23:00.001924
/root/homework/README.md
Tick! The time is: 2019-06-02 23:23:00.001803
/root/homework/README.md
Tick! The time is: 2019-06-03 23:23:00.001897
/root/homework/README.md
Tick! The time is: 2019-06-04 23:23:00.001847
/root/homework/README.md
Tick! The time is: 2019-06-05 23:23:00.001933
/root/homework/README.md
Tick! The time is: 2019-06-06 23:23:00.001862
/root/homework/README.md
Tick! The time is: 2019-06-07 23:23:00.001912
/root/homework/README.md
Tick! The time is: 2019-06-08 23:23:00.001866
/root/homework/README.md
Tick! The time is: 2019-06-09 23:23:00.001848
/root/homework/README.md
Tick! The time is: 2019-06-10 23:23:00.002105
/root/homework/README.md
Tick! The time is: 2019-06-11 23:23:00.001802
/root/homework/test_wdj.py
Tick! The time is: 2019-06-12 23:23:00.001960
/root/homework/access.log
Tick! The time is: 2019-06-13 23:23:00.002016
/root/homework/README.md
Tick! The time is: 2019-06-14 23:23:00.001786
/root/homework/README.md
Tick! The time is: 2019-06-15 23:23:00.001845
/root/homework/README.md
Tick! The time is: 2019-06-16 23:23:00.002046
/root/homework/README.md
Tick! The time is: 2019-06-17 23:23:00.001935
/root/homework/README.md
Tick! The time is: 2019-06-18 23:23:00.001861
/root/homework/README.md
Tick! The time is: 2019-06-19 23:23:00.001808
/root/homework/README.md
Tick! The time is: 2019-06-20 23:23:00.001970
/root/homework/README.md
Tick! The time is: 2019-06-21 23:23:00.002024
/root/homework/README.md
Tick! The time is: 2019-06-22 23:23:00.001877
/root/homework/README.md
Tick! The time is: 2019-06-23 23:23:00.001929
/root/homework/README.md
Tick! The time is: 2019-06-24 23:23:00.001830
/root/homework/README.md
Tick! The time is: 2019-06-25 23:23:00.001812
/root/homework/README.md
Tick! The time is: 2019-06-26 23:23:00.002028
/root/homework/README.md
Tick! The time is: 2019-06-27 23:23:00.002065
/root/homework/README.md
Tick! The time is: 2019-06-28 23:23:00.017080
/root/homework/README.md
Tick! The time is: 2019-06-29 23:23:00.001783
/root/homework/README.md
Tick! The time is: 2019-06-30 23:23:00.002075
/root/homework/README.md
Tick! The time is: 2019-07-01 23:23:00.001809
/root/homework/flask_test/flask_test/lib/python3.6/site-packages/setuptools/command/__pycache__/install_egg_info.cpython-36.pyc
Tick! The time is: 2019-07-02 23:23:00.002155
/root/homework/flask_test/flask_test/lib/python3.6/site-packages/setuptools/command/__pycache__/alias.cpython-36.pyc
Tick! The time is: 2019-07-03 23:23:00.001966
/root/homework/flask_test/flask_test/lib/python3.6/site-packages/setuptools/command/__pycache__/install_lib.cpython-36.pyc
Tick! The time is: 2019-07-04 23:23:00.001874
/root/homework/flask_test/flask_test/lib/python3.6/site-packages/setuptools/command/__pycache__/test.cpython-36.pyc
Tick! The time is: 2019-07-05 23:23:00.002304
/root/homework/flask_test/flask_test/lib/python3.6/site-packages/setuptools/command/__pycache__/build_ext.cpython-36.pyc
Tick! The time is: 2019-07-06 23:23:00.001704
/root/homework/flask_test/flask_test/lib/python3.6/site-packages/setuptools/command/__pycache__/dist_info.cpython-36.pyc
Tick! The time is: 2019-07-07 23:23:00.001890
/root/homework/flask_test/flask_test/lib/python3.6/site-packages/setuptools/command/__pycache__/bdist_egg.cpython-36.pyc
Tick! The time is: 2019-07-08 23:23:00.001920
/root/homework/flask_test/flask_test/lib/python3.6/site-packages/setuptools/command/__pycache__/bdist_wininst.cpython-36.pyc
Tick! The time is: 2019-07-09 23:23:00.001935
/root/homework/flask_test/logs/logs/access.log
Tick! The time is: 2019-07-10 23:23:00.001881
/root/homework/flask_test/logs/logs/error.log
Tick! The time is: 2019-07-11 23:23:00.001970
/root/homework/flask_test/flask_test/lib/python3.6/site-packages/setuptools/command/__pycache__/py36compat.cpython-36.pyc
Tick! The time is: 2019-07-12 23:23:00.001873
/root/homework/flask_test/flask_test/lib/python3.6/site-packages/setuptools/command/__pycache__/__init__.cpython-36.pyc
Tick! The time is: 2019-07-13 23:23:00.019349
/root/homework/flask_test/flask_test/lib/python3.6/site-packages/setuptools/command/__pycache__/saveopts.cpython-36.pyc
Tick! The time is: 2019-07-14 23:23:00.002229
/root/homework/flask_test/flask_test/lib/python3.6/site-packages/setuptools/command/__pycache__/setopt.cpython-36.pyc
Tick! The time is: 2019-07-15 23:23:00.001903
/root/homework/flask_test/flask_test/lib/python3.6/site-packages/setuptools/command/__pycache__/easy_install.cpython-36.pyc
Tick! The time is: 2019-07-16 23:23:00.001942
/root/homework/flask_test/flask_test/lib/python3.6/site-packages/setuptools/command/__pycache__/upload.cpython-36.pyc
Tick! The time is: 2019-07-17 23:23:00.002077
/root/homework/docker_test/flask_demo/test.py
Tick! The time is: 2019-07-18 23:23:00.001905
/root/homework/docker_test/flask_demo/api_client.pyTo git@github.com:dajun928/Tool.git
   42b8568..05e487d  master -> master
To git@github.com:dajun928/Tool.git
   05e487d..bba4c2b  master -> master
To git@github.com:dajun928/Tool.git
   bba4c2b..d863a4d  master -> master
To git@github.com:dajun928/Tool.git
   d863a4d..f7f8d63  master -> master
To git@github.com:dajun928/Tool.git
   f7f8d63..ec98739  master -> master
To git@github.com:dajun928/Tool.git
   ec98739..736a962  master -> master
To git@github.com:dajun928/Tool.git
   736a962..f080223  master -> master
To git@github.com:dajun928/Tool.git
   f080223..30280a0  master -> master
To git@github.com:dajun928/Tool.git
   30280a0..dfa3f7c  master -> master
To git@github.com:dajun928/Tool.git
   dfa3f7c..ae706e3  master -> master
To git@github.com:dajun928/Tool.git
   ae706e3..f038ec3  master -> master
To git@github.com:dajun928/Tool.git
   f038ec3..74ef15f  master -> master
To git@github.com:dajun928/Tool.git
   74ef15f..d615679  master -> master
To git@github.com:dajun928/Tool.git
   d615679..3f42e2a  master -> master
To git@github.com:dajun928/Tool.git
   3f42e2a..f368d8e  master -> master
To git@github.com:dajun928/Tool.git
   f368d8e..cc9954a  master -> master
To git@github.com:dajun928/Tool.git
   cc9954a..9fad207  master -> master
To git@github.com:dajun928/Tool.git
   9fad207..f1d8973  master -> master
To git@github.com:dajun928/Tool.git
   f1d8973..d642025  master -> master
To git@github.com:dajun928/Tool.git
   d642025..c5db707  master -> master
To git@github.com:dajun928/Tool.git
   c5db707..e16af26  master -> master
To git@github.com:dajun928/Tool.git
   e16af26..f40f1ce  master -> master
To git@github.com:dajun928/Tool.git
   f40f1ce..57ad1f4  master -> master
To git@github.com:dajun928/Tool.git
   57ad1f4..8268729  master -> master
Job "cut_single_file (trigger: cron[hour='23', minute='22'], next run at: 2019-08-13 23:22:00 CST)" raised an exception
Traceback (most recent call last):
  File "/root/anaconda3/lib/python3.6/site-packages/apscheduler/executors/base.py", line 125, in run_job
    retval = job.func(*job.args, **job.kwargs)
  File "control.py", line 56, in cut_single_file
    shutil.move(src_file, dsc_path)
  File "/root/anaconda3/lib/python3.6/shutil.py", line 542, in move
    raise Error("Destination path '%s' already exists" % real_dst)
shutil.Error: Destination path '/root/Projects/gitdemo/test/Tool/Tool/test.py' already exists
To git@github.com:dajun928/Tool.git
   8268729..b1dedcb  master -> master
Job "cut_single_file (trigger: cron[hour='23', minute='22'], next run at: 2019-08-14 23:22:00 CST)" raised an exception
Traceback (most recent call last):
  File "/root/anaconda3/lib/python3.6/site-packages/apscheduler/executors/base.py", line 125, in run_job
    retval = job.func(*job.args, **job.kwargs)
  File "control.py", line 56, in cut_single_file
    shutil.move(src_file, dsc_path)
  File "/root/anaconda3/lib/python3.6/shutil.py", line 542, in move
    raise Error("Destination path '%s' already exists" % real_dst)
shutil.Error: Destination path '/root/Projects/gitdemo/test/Tool/Tool/test.py' already exists
To git@github.com:dajun928/Tool.git
   b1dedcb..9c4a6bd  master -> master
Job "cut_single_file (trigger: cron[hour='23', minute='22'], next run at: 2019-08-15 23:22:00 CST)" raised an exception
Traceback (most recent call last):
  File "/root/anaconda3/lib/python3.6/site-packages/apscheduler/executors/base.py", line 125, in run_job
    retval = job.func(*job.args, **job.kwargs)
  File "control.py", line 56, in cut_single_file
    shutil.move(src_file, dsc_path)
  File "/root/anaconda3/lib/python3.6/shutil.py", line 542, in move
    raise Error("Destination path '%s' already exists" % real_dst)
shutil.Error: Destination path '/root/Projects/gitdemo/test/Tool/Tool/test.py' already exists
To git@github.com:dajun928/Tool.git
   9c4a6bd..b361909  master -> master
Job "cut_single_file (trigger: cron[hour='23', minute='22'], next run at: 2019-08-16 23:22:00 CST)" raised an exception
Traceback (most recent call last):
  File "/root/anaconda3/lib/python3.6/site-packages/apscheduler/executors/base.py", line 125, in run_job
    retval = job.func(*job.args, **job.kwargs)
  File "control.py", line 56, in cut_single_file
    shutil.move(src_file, dsc_path)
  File "/root/anaconda3/lib/python3.6/shutil.py", line 542, in move
    raise Error("Destination path '%s' already exists" % real_dst)
shutil.Error: Destination path '/root/Projects/gitdemo/test/Tool/Tool/test.py' already exists
To git@github.com:dajun928/Tool.git
   b361909..3f760cf  master -> master
Job "cut_single_file (trigger: cron[hour='23', minute='22'], next run at: 2019-08-17 23:22:00 CST)" raised an exception
Traceback (most recent call last):
  File "/root/anaconda3/lib/python3.6/site-packages/apscheduler/executors/base.py", line 125, in run_job
    retval = job.func(*job.args, **job.kwargs)
  File "control.py", line 56, in cut_single_file
    shutil.move(src_file, dsc_path)
  File "/root/anaconda3/lib/python3.6/shutil.py", line 542, in move
    raise Error("Destination path '%s' already exists" % real_dst)
shutil.Error: Destination path '/root/Projects/gitdemo/test/Tool/Tool/test.py' already exists
To git@github.com:dajun928/Tool.git
   3f760cf..f9e42ed  master -> master
Job "cut_single_file (trigger: cron[hour='23', minute='22'], next run at: 2019-08-18 23:22:00 CST)" raised an exception
Traceback (most recent call last):
  File "/root/anaconda3/lib/python3.6/site-packages/apscheduler/executors/base.py", line 125, in run_job
    retval = job.func(*job.args, **job.kwargs)
  File "control.py", line 56, in cut_single_file
    shutil.move(src_file, dsc_path)
  File "/root/anaconda3/lib/python3.6/shutil.py", line 542, in move
    raise Error("Destination path '%s' already exists" % real_dst)
shutil.Error: Destination path '/root/Projects/gitdemo/test/Tool/Tool/test.py' already exists
To git@github.com:dajun928/Tool.git
   f9e42ed..713d158  master -> master
Job "cut_single_file (trigger: cron[hour='23', minute='22'], next run at: 2019-08-19 23:22:00 CST)" raised an exception
Traceback (most recent call last):
  File "/root/anaconda3/lib/python3.6/site-packages/apscheduler/executors/base.py", line 125, in run_job
    retval = job.func(*job.args, **job.kwargs)
  File "control.py", line 56, in cut_single_file
    shutil.move(src_file, dsc_path)
  File "/root/anaconda3/lib/python3.6/shutil.py", line 542, in move
    raise Error("Destination path '%s' already exists" % real_dst)
shutil.Error: Destination path '/root/Projects/gitdemo/test/Tool/Tool/test.py' already exists
To git@github.com:dajun928/Tool.git
   713d158..de9be01  master -> master
Job "cut_single_file (trigger: cron[hour='23', minute='22'], next run at: 2019-08-20 23:22:00 CST)" raised an exception
Traceback (most recent call last):
  File "/root/anaconda3/lib/python3.6/site-packages/apscheduler/executors/base.py", line 125, in run_job
    retval = job.func(*job.args, **job.kwargs)
  File "control.py", line 56, in cut_single_file
    shutil.move(src_file, dsc_path)
  File "/root/anaconda3/lib/python3.6/shutil.py", line 542, in move
    raise Error("Destination path '%s' already exists" % real_dst)
shutil.Error: Destination path '/root/Projects/gitdemo/test/Tool/Tool/test.py' already exists
To git@github.com:dajun928/Tool.git
   de9be01..a98cfa1  master -> master
Job "cut_single_file (trigger: cron[hour='23', minute='22'], next run at: 2019-08-21 23:22:00 CST)" raised an exception
Traceback (most recent call last):
  File "/root/anaconda3/lib/python3.6/site-packages/apscheduler/executors/base.py", line 125, in run_job
    retval = job.func(*job.args, **job.kwargs)
  File "control.py", line 56, in cut_single_file
    shutil.move(src_file, dsc_path)
  File "/root/anaconda3/lib/python3.6/shutil.py", line 542, in move
    raise Error("Destination path '%s' already exists" % real_dst)
shutil.Error: Destination path '/root/Projects/gitdemo/test/Tool/Tool/test.py' already exists
To git@github.com:dajun928/Tool.git
   a98cfa1..2f715a3  master -> master
Job "cut_single_file (trigger: cron[hour='23', minute='22'], next run at: 2019-08-22 23:22:00 CST)" raised an exception
Traceback (most recent call last):
  File "/root/anaconda3/lib/python3.6/site-packages/apscheduler/executors/base.py", line 125, in run_job
    retval = job.func(*job.args, **job.kwargs)
  File "control.py", line 56, in cut_single_file
    shutil.move(src_file, dsc_path)
  File "/root/anaconda3/lib/python3.6/shutil.py", line 542, in move
    raise Error("Destination path '%s' already exists" % real_dst)
shutil.Error: Destination path '/root/Projects/gitdemo/test/Tool/Tool/test.py' already exists
To git@github.com:dajun928/Tool.git
   2f715a3..870e24c  master -> master
Job "cut_single_file (trigger: cron[hour='23', minute='22'], next run at: 2019-08-23 23:22:00 CST)" raised an exception
Traceback (most recent call last):
  File "/root/anaconda3/lib/python3.6/site-packages/apscheduler/executors/base.py", line 125, in run_job
    retval = job.func(*job.args, **job.kwargs)
  File "control.py", line 56, in cut_single_file
    shutil.move(src_file, dsc_path)
  File "/root/anaconda3/lib/python3.6/shutil.py", line 542, in move
    raise Error("Destination path '%s' already exists" % real_dst)
shutil.Error: Destination path '/root/Projects/gitdemo/test/Tool/Tool/test.py' already exists
To git@github.com:dajun928/Tool.git
   870e24c..ee0661f  master -> master
Job "cut_single_file (trigger: cron[hour='23', minute='22'], next run at: 2019-08-24 23:22:00 CST)" raised an exception
Traceback (most recent call last):
  File "/root/anaconda3/lib/python3.6/site-packages/apscheduler/executors/base.py", line 125, in run_job
    retval = job.func(*job.args, **job.kwargs)
  File "control.py", line 56, in cut_single_file
    shutil.move(src_file, dsc_path)
  File "/root/anaconda3/lib/python3.6/shutil.py", line 542, in move
    raise Error("Destination path '%s' already exists" % real_dst)
shutil.Error: Destination path '/root/Projects/gitdemo/test/Tool/Tool/test.py' already exists
To git@github.com:dajun928/Tool.git
   ee0661f..9758ca6  master -> master
Job "cut_single_file (trigger: cron[hour='23', minute='22'], next run at: 2019-08-25 23:22:00 CST)" raised an exception
Traceback (most recent call last):
  File "/root/anaconda3/lib/python3.6/site-packages/apscheduler/executors/base.py", line 125, in run_job
    retval = job.func(*job.args, **job.kwargs)
  File "control.py", line 56, in cut_single_file
    shutil.move(src_file, dsc_path)
  File "/root/anaconda3/lib/python3.6/shutil.py", line 542, in move
    raise Error("Destination path '%s' already exists" % real_dst)
shutil.Error: Destination path '/root/Projects/gitdemo/test/Tool/Tool/test.py' already exists
To git@github.com:dajun928/Tool.git
   9758ca6..1b3cf91  master -> master
Job "cut_single_file (trigger: cron[hour='23', minute='22'], next run at: 2019-08-26 23:22:00 CST)" raised an exception
Traceback (most recent call last):
  File "/root/anaconda3/lib/python3.6/site-packages/apscheduler/executors/base.py", line 125, in run_job
    retval = job.func(*job.args, **job.kwargs)
  File "control.py", line 56, in cut_single_file
    shutil.move(src_file, dsc_path)
  File "/root/anaconda3/lib/python3.6/shutil.py", line 542, in move
    raise Error("Destination path '%s' already exists" % real_dst)
shutil.Error: Destination path '/root/Projects/gitdemo/test/Tool/Tool/test.py' already exists
To git@github.com:dajun928/Tool.git
   1b3cf91..3cea751  master -> master
Job "cut_single_file (trigger: cron[hour='23', minute='22'], next run at: 2019-08-27 23:22:00 CST)" raised an exception
Traceback (most recent call last):
  File "/root/anaconda3/lib/python3.6/site-packages/apscheduler/executors/base.py", line 125, in run_job
    retval = job.func(*job.args, **job.kwargs)
  File "control.py", line 56, in cut_single_file
    shutil.move(src_file, dsc_path)
  File "/root/anaconda3/lib/python3.6/shutil.py", line 542, in move
    raise Error("Destination path '%s' already exists" % real_dst)
shutil.Error: Destination path '/root/Projects/gitdemo/test/Tool/Tool/test.py' already exists
To git@github.com:dajun928/Tool.git
   3cea751..710b423  master -> master
Job "cut_single_file (trigger: cron[hour='23', minute='22'], next run at: 2019-08-28 23:22:00 CST)" raised an exception
Traceback (most recent call last):
  File "/root/anaconda3/lib/python3.6/site-packages/apscheduler/executors/base.py", line 125, in run_job
    retval = job.func(*job.args, **job.kwargs)
  File "control.py", line 56, in cut_single_file
    shutil.move(src_file, dsc_path)
  File "/root/anaconda3/lib/python3.6/shutil.py", line 542, in move
    raise Error("Destination path '%s' already exists" % real_dst)
shutil.Error: Destination path '/root/Projects/gitdemo/test/Tool/Tool/test.py' already exists
To git@github.com:dajun928/Tool.git
   710b423..afdfd70  master -> master
Job "cut_single_file (trigger: cron[hour='23', minute='22'], next run at: 2019-08-29 23:22:00 CST)" raised an exception
Traceback (most recent call last):
  File "/root/anaconda3/lib/python3.6/site-packages/apscheduler/executors/base.py", line 125, in run_job
    retval = job.func(*job.args, **job.kwargs)
  File "control.py", line 56, in cut_single_file
    shutil.move(src_file, dsc_path)
  File "/root/anaconda3/lib/python3.6/shutil.py", line 542, in move
    raise Error("Destination path '%s' already exists" % real_dst)
shutil.Error: Destination path '/root/Projects/gitdemo/test/Tool/Tool/test.py' already exists
To git@github.com:dajun928/Tool.git
   afdfd70..e7f2153  master -> master
Job "cut_single_file (trigger: cron[hour='23', minute='22'], next run at: 2019-08-30 23:22:00 CST)" raised an exception
Traceback (most recent call last):
  File "/root/anaconda3/lib/python3.6/site-packages/apscheduler/executors/base.py", line 125, in run_job
    retval = job.func(*job.args, **job.kwargs)
  File "control.py", line 56, in cut_single_file
    shutil.move(src_file, dsc_path)
  File "/root/anaconda3/lib/python3.6/shutil.py", line 542, in move
    raise Error("Destination path '%s' already exists" % real_dst)
shutil.Error: Destination path '/root/Projects/gitdemo/test/Tool/Tool/test.py' already exists
To git@github.com:dajun928/Tool.git
   e7f2153..2fc16c8  master -> master
Job "cut_single_file (trigger: cron[hour='23', minute='22'], next run at: 2019-08-31 23:22:00 CST)" raised an exception
Traceback (most recent call last):
  File "/root/anaconda3/lib/python3.6/site-packages/apscheduler/executors/base.py", line 125, in run_job
    retval = job.func(*job.args, **job.kwargs)
  File "control.py", line 56, in cut_single_file
    shutil.move(src_file, dsc_path)
  File "/root/anaconda3/lib/python3.6/shutil.py", line 542, in move
    raise Error("Destination path '%s' already exists" % real_dst)
shutil.Error: Destination path '/root/Projects/gitdemo/test/Tool/Tool/test.py' already exists
To git@github.com:dajun928/Tool.git
   2fc16c8..1b5df43  master -> master
Job "cut_single_file (trigger: cron[hour='23', minute='22'], next run at: 2019-09-01 23:22:00 CST)" raised an exception
Traceback (most recent call last):
  File "/root/anaconda3/lib/python3.6/site-packages/apscheduler/executors/base.py", line 125, in run_job
    retval = job.func(*job.args, **job.kwargs)
  File "control.py", line 56, in cut_single_file
    shutil.move(src_file, dsc_path)
  File "/root/anaconda3/lib/python3.6/shutil.py", line 542, in move
    raise Error("Destination path '%s' already exists" % real_dst)
shutil.Error: Destination path '/root/Projects/gitdemo/test/Tool/Tool/test.py' already exists
To git@github.com:dajun928/Tool.git
   1b5df43..dd67896  master -> master
Job "cut_single_file (trigger: cron[hour='23', minute='22'], next run at: 2019-09-02 23:22:00 CST)" raised an exception
Traceback (most recent call last):
  File "/root/anaconda3/lib/python3.6/site-packages/apscheduler/executors/base.py", line 125, in run_job
    retval = job.func(*job.args, **job.kwargs)
  File "control.py", line 56, in cut_single_file
    shutil.move(src_file, dsc_path)
  File "/root/anaconda3/lib/python3.6/shutil.py", line 542, in move
    raise Error("Destination path '%s' already exists" % real_dst)
shutil.Error: Destination path '/root/Projects/gitdemo/test/Tool/Tool/test.py' already exists
To git@github.com:dajun928/Tool.git
   dd67896..8c873fd  master -> master
Job "cut_single_file (trigger: cron[hour='23', minute='22'], next run at: 2019-09-03 23:22:00 CST)" raised an exception
Traceback (most recent call last):
  File "/root/anaconda3/lib/python3.6/site-packages/apscheduler/executors/base.py", line 125, in run_job
    retval = job.func(*job.args, **job.kwargs)
  File "control.py", line 56, in cut_single_file
    shutil.move(src_file, dsc_path)
  File "/root/anaconda3/lib/python3.6/shutil.py", line 542, in move
    raise Error("Destination path '%s' already exists" % real_dst)
shutil.Error: Destination path '/root/Projects/gitdemo/test/Tool/Tool/test.py' already exists
To git@github.com:dajun928/Tool.git
   8c873fd..92cff35  master -> master
Job "cut_single_file (trigger: cron[hour='23', minute='22'], next run at: 2019-09-04 23:22:00 CST)" raised an exception
Traceback (most recent call last):
  File "/root/anaconda3/lib/python3.6/site-packages/apscheduler/executors/base.py", line 125, in run_job
    retval = job.func(*job.args, **job.kwargs)
  File "control.py", line 56, in cut_single_file
    shutil.move(src_file, dsc_path)
  File "/root/anaconda3/lib/python3.6/shutil.py", line 542, in move
    raise Error("Destination path '%s' already exists" % real_dst)
shutil.Error: Destination path '/root/Projects/gitdemo/test/Tool/Tool/test.py' already exists
To git@github.com:dajun928/Tool.git
   92cff35..f0b81ca  master -> master
Job "cut_single_file (trigger: cron[hour='23', minute='22'], next run at: 2019-09-05 23:22:00 CST)" raised an exception
Traceback (most recent call last):
  File "/root/anaconda3/lib/python3.6/site-packages/apscheduler/executors/base.py", line 125, in run_job
    retval = job.func(*job.args, **job.kwargs)
  File "control.py", line 56, in cut_single_file
    shutil.move(src_file, dsc_path)
  File "/root/anaconda3/lib/python3.6/shutil.py", line 542, in move
    raise Error("Destination path '%s' already exists" % real_dst)
shutil.Error: Destination path '/root/Projects/gitdemo/test/Tool/Tool/test.py' already exists
To git@github.com:dajun928/Tool.git
   f0b81ca..c1ba417  master -> master
Job "cut_single_file (trigger: cron[hour='23', minute='22'], next run at: 2019-09-06 23:22:00 CST)" raised an exception
Traceback (most recent call last):
  File "/root/anaconda3/lib/python3.6/site-packages/apscheduler/executors/base.py", line 125, in run_job
    retval = job.func(*job.args, **job.kwargs)
  File "control.py", line 56, in cut_single_file
    shutil.move(src_file, dsc_path)
  File "/root/anaconda3/lib/python3.6/shutil.py", line 542, in move
    raise Error("Destination path '%s' already exists" % real_dst)
shutil.Error: Destination path '/root/Projects/gitdemo/test/Tool/Tool/test.py' already exists
To git@github.com:dajun928/Tool.git
   c1ba417..400580f  master -> master
Job "cut_single_file (trigger: cron[hour='23', minute='22'], next run at: 2019-09-07 23:22:00 CST)" raised an exception
Traceback (most recent call last):
  File "/root/anaconda3/lib/python3.6/site-packages/apscheduler/executors/base.py", line 125, in run_job
    retval = job.func(*job.args, **job.kwargs)
  File "control.py", line 56, in cut_single_file
    shutil.move(src_file, dsc_path)
  File "/root/anaconda3/lib/python3.6/shutil.py", line 542, in move
    raise Error("Destination path '%s' already exists" % real_dst)
shutil.Error: Destination path '/root/Projects/gitdemo/test/Tool/Tool/test.py' already exists
To git@github.com:dajun928/Tool.git
   400580f..42fc699  master -> master
Job "cut_single_file (trigger: cron[hour='23', minute='22'], next run at: 2019-09-08 23:22:00 CST)" raised an exception
Traceback (most recent call last):
  File "/root/anaconda3/lib/python3.6/site-packages/apscheduler/executors/base.py", line 125, in run_job
    retval = job.func(*job.args, **job.kwargs)
  File "control.py", line 56, in cut_single_file
    shutil.move(src_file, dsc_path)
  File "/root/anaconda3/lib/python3.6/shutil.py", line 542, in move
    raise Error("Destination path '%s' already exists" % real_dst)
shutil.Error: Destination path '/root/Projects/gitdemo/test/Tool/Tool/test.py' already exists
To git@github.com:dajun928/Tool.git
   42fc699..f5a0ccf  master -> master
Job "cut_single_file (trigger: cron[hour='23', minute='22'], next run at: 2019-09-09 23:22:00 CST)" raised an exception
Traceback (most recent call last):
  File "/root/anaconda3/lib/python3.6/site-packages/apscheduler/executors/base.py", line 125, in run_job
    retval = job.func(*job.args, **job.kwargs)
  File "control.py", line 56, in cut_single_file
    shutil.move(src_file, dsc_path)
  File "/root/anaconda3/lib/python3.6/shutil.py", line 542, in move
    raise Error("Destination path '%s' already exists" % real_dst)
shutil.Error: Destination path '/root/Projects/gitdemo/test/Tool/Tool/test.py' already exists
To git@github.com:dajun928/Tool.git
   f5a0ccf..f05047a  master -> master
Job "cut_single_file (trigger: cron[hour='23', minute='22'], next run at: 2019-09-10 23:22:00 CST)" raised an exception
Traceback (most recent call last):
  File "/root/anaconda3/lib/python3.6/site-packages/apscheduler/executors/base.py", line 125, in run_job
    retval = job.func(*job.args, **job.kwargs)
  File "control.py", line 56, in cut_single_file
    shutil.move(src_file, dsc_path)
  File "/root/anaconda3/lib/python3.6/shutil.py", line 542, in move
    raise Error("Destination path '%s' already exists" % real_dst)
shutil.Error: Destination path '/root/Projects/gitdemo/test/Tool/Tool/test.py' already exists
To git@github.com:dajun928/Tool.git
   f05047a..11a1f0a  master -> master
Job "cut_single_file (trigger: cron[hour='23', minute='22'], next run at: 2019-09-11 23:22:00 CST)" raised an exception
Traceback (most recent call last):
  File "/root/anaconda3/lib/python3.6/site-packages/apscheduler/executors/base.py", line 125, in run_job
    retval = job.func(*job.args, **job.kwargs)
  File "control.py", line 56, in cut_single_file
    shutil.move(src_file, dsc_path)
  File "/root/anaconda3/lib/python3.6/shutil.py", line 542, in move
    raise Error("Destination path '%s' already exists" % real_dst)
shutil.Error: Destination path '/root/Projects/gitdemo/test/Tool/Tool/test.py' already exists
To git@github.com:dajun928/Tool.git
   11a1f0a..731e504  master -> master
Job "cut_single_file (trigger: cron[hour='23', minute='22'], next run at: 2019-09-12 23:22:00 CST)" raised an exception
Traceback (most recent call last):
  File "/root/anaconda3/lib/python3.6/site-packages/apscheduler/executors/base.py", line 125, in run_job
    retval = job.func(*job.args, **job.kwargs)
  File "control.py", line 56, in cut_single_file
    shutil.move(src_file, dsc_path)
  File "/root/anaconda3/lib/python3.6/shutil.py", line 542, in move
    raise Error("Destination path '%s' already exists" % real_dst)
shutil.Error: Destination path '/root/Projects/gitdemo/test/Tool/Tool/test.py' already exists
To git@github.com:dajun928/Tool.git
   731e504..84c3003  master -> master
Job "cut_single_file (trigger: cron[hour='23', minute='22'], next run at: 2019-09-13 23:22:00 CST)" raised an exception
Traceback (most recent call last):
  File "/root/anaconda3/lib/python3.6/site-packages/apscheduler/executors/base.py", line 125, in run_job
    retval = job.func(*job.args, **job.kwargs)
  File "control.py", line 56, in cut_single_file
    shutil.move(src_file, dsc_path)
  File "/root/anaconda3/lib/python3.6/shutil.py", line 542, in move
    raise Error("Destination path '%s' already exists" % real_dst)
shutil.Error: Destination path '/root/Projects/gitdemo/test/Tool/Tool/test.py' already exists
To git@github.com:dajun928/Tool.git
   84c3003..93d722f  master -> master
Job "cut_single_file (trigger: cron[hour='23', minute='22'], next run at: 2019-09-14 23:22:00 CST)" raised an exception
Traceback (most recent call last):
  File "/root/anaconda3/lib/python3.6/site-packages/apscheduler/executors/base.py", line 125, in run_job
    retval = job.func(*job.args, **job.kwargs)
  File "control.py", line 56, in cut_single_file
    shutil.move(src_file, dsc_path)
  File "/root/anaconda3/lib/python3.6/shutil.py", line 542, in move
    raise Error("Destination path '%s' already exists" % real_dst)
shutil.Error: Destination path '/root/Projects/gitdemo/test/Tool/Tool/test.py' already exists
To git@github.com:dajun928/Tool.git
   93d722f..3f28655  master -> master
Job "cut_single_file (trigger: cron[hour='23', minute='22'], next run at: 2019-09-15 23:22:00 CST)" raised an exception
Traceback (most recent call last):
  File "/root/anaconda3/lib/python3.6/site-packages/apscheduler/executors/base.py", line 125, in run_job
    retval = job.func(*job.args, **job.kwargs)
  File "control.py", line 56, in cut_single_file
    shutil.move(src_file, dsc_path)
  File "/root/anaconda3/lib/python3.6/shutil.py", line 542, in move
    raise Error("Destination path '%s' already exists" % real_dst)
shutil.Error: Destination path '/root/Projects/gitdemo/test/Tool/Tool/test.py' already exists
To git@github.com:dajun928/Tool.git
   3f28655..831d354  master -> master
Job "cut_single_file (trigger: cron[hour='23', minute='22'], next run at: 2019-09-16 23:22:00 CST)" raised an exception
Traceback (most recent call last):
  File "/root/anaconda3/lib/python3.6/site-packages/apscheduler/executors/base.py", line 125, in run_job
    retval = job.func(*job.args, **job.kwargs)
  File "control.py", line 56, in cut_single_file
    shutil.move(src_file, dsc_path)
  File "/root/anaconda3/lib/python3.6/shutil.py", line 542, in move
    raise Error("Destination path '%s' already exists" % real_dst)
shutil.Error: Destination path '/root/Projects/gitdemo/test/Tool/Tool/test.py' already exists

Tick! The time is: 2019-07-19 23:23:00.001941
/root/homework/docker_test/flask_demo/__init__.py
Tick! The time is: 2019-07-20 23:23:00.001815
/root/homework/docker_test/flask_demo/requirements.txt
Tick! The time is: 2019-07-21 23:23:00.001788
/root/homework/docker_test/flask_demo/api_server.py
Tick! The time is: 2019-07-22 23:23:00.001773
/root/homework/docker_test/Dockerfile
Tick! The time is: 2019-07-23 23:23:00.002048
/root/homework/flask_test/flask_test/lib/python3.6/site-packages/setuptools/command/__pycache__/build_py.cpython-36.pyc
Tick! The time is: 2019-07-24 23:23:00.001869
/root/homework/flask_test/flask_test/lib/python3.6/site-packages/setuptools/command/__pycache__/sdist.cpython-36.pyc
Tick! The time is: 2019-07-25 23:23:00.002290
/root/homework/flask_test/flask_test/lib/python3.6/site-packages/setuptools/command/__pycache__/install_scripts.cpython-36.pyc
Tick! The time is: 2019-07-26 23:23:00.002048
/root/homework/flask_test/flask_test/lib/python3.6/site-packages/setuptools/command/__pycache__/install.cpython-36.pyc
Tick! The time is: 2019-07-27 23:23:00.001710
/root/homework/flask_test/flask_test/lib/python3.6/site-packages/setuptools/command/__pycache__/build_clib.cpython-36.pyc
Tick! The time is: 2019-07-28 23:23:00.002015
/root/homework/flask_test/flask_test/lib/python3.6/site-packages/setuptools/command/__pycache__/bdist_rpm.cpython-36.pyc
Tick! The time is: 2019-07-29 23:23:00.002032
/root/homework/flask_test/flask_test/lib/python3.6/site-packages/setuptools/command/__pycache__/develop.cpython-36.pyc
Tick! The time is: 2019-07-30 23:23:00.001793
/root/homework/flask_test/flask_test/lib/python3.6/site-packages/setuptools/command/__pycache__/rotate.cpython-36.pyc
Tick! The time is: 2019-07-31 23:23:00.002129
/root/homework/flask_test/flask_test/lib/python3.6/site-packages/setuptools/command/__pycache__/register.cpython-36.pyc
Tick! The time is: 2019-08-01 23:23:00.001938
/root/homework/flask_test/flask_test/lib/python3.6/site-packages/setuptools/command/__pycache__/upload_docs.cpython-36.pyc
Tick! The time is: 2019-08-02 23:23:00.001857
/root/homework/flask_test/flask_test/lib/python3.6/site-packages/setuptools/command/__pycache__/egg_info.cpython-36.pyc
Tick! The time is: 2019-08-03 23:23:00.001823
/root/homework/flask_test/flask_test/lib/python3.6/site-packages/setuptools/command/upload.py
Tick! The time is: 2019-08-04 23:23:00.002009
/root/homework/flask_test/flask_test/lib/python3.6/site-packages/setuptools/command/install_lib.py
Tick! The time is: 2019-08-05 23:23:00.002186
/root/homework/flask_test/flask_test/lib/python3.6/site-packages/setuptools/command/build_clib.py
Tick! The time is: 2019-08-06 23:23:00.001805
/root/homework/flask_test/flask_test/lib/python3.6/site-packages/setuptools/command/build_ext.py
Tick! The time is: 2019-08-07 23:23:00.001858
/root/homework/flask_test/flask_test/lib/python3.6/site-packages/setuptools/command/saveopts.py
Tick! The time is: 2019-08-08 23:23:00.001835
/root/homework/flask_test/flask_test/lib/python3.6/site-packages/setuptools/command/launcher manifest.xml
Tick! The time is: 2019-08-09 23:23:00.001957
/root/homework/flask_test/flask_test/lib/python3.6/site-packages/setuptools/command/dist_info.py
Tick! The time is: 2019-08-10 23:23:00.001948
/root/homework/flask_test/flask_test/lib/python3.6/site-packages/setuptools/command/setopt.py
Tick! The time is: 2019-08-11 23:23:00.001904
/root/homework/flask_test/flask_test/lib/python3.6/site-packages/setuptools/command/test.py
Tick! The time is: 2019-08-12 23:23:00.001779
/root/homework/flask_test/flask_test/lib/python3.6/site-packages/setuptools/command/test.py
Tick! The time is: 2019-08-13 23:23:00.002369
/root/homework/flask_test/flask_test/lib/python3.6/site-packages/setuptools/command/test.py
Tick! The time is: 2019-08-14 23:23:00.001941
/root/homework/flask_test/flask_test/lib/python3.6/site-packages/setuptools/command/test.py
Tick! The time is: 2019-08-15 23:23:00.001837
/root/homework/flask_test/flask_test/lib/python3.6/site-packages/setuptools/command/test.py
Tick! The time is: 2019-08-16 23:23:00.002219
/root/homework/flask_test/flask_test/lib/python3.6/site-packages/setuptools/command/test.py
Tick! The time is: 2019-08-17 23:23:00.001931
/root/homework/flask_test/flask_test/lib/python3.6/site-packages/setuptools/command/test.py
Tick! The time is: 2019-08-18 23:23:00.001813
/root/homework/flask_test/flask_test/lib/python3.6/site-packages/setuptools/command/test.py
Tick! The time is: 2019-08-19 23:23:00.001946
/root/homework/flask_test/flask_test/lib/python3.6/site-packages/setuptools/command/test.py
Tick! The time is: 2019-08-20 23:23:00.001874
/root/homework/flask_test/flask_test/lib/python3.6/site-packages/setuptools/command/test.py
Tick! The time is: 2019-08-21 23:23:00.002088
/root/homework/flask_test/flask_test/lib/python3.6/site-packages/setuptools/command/test.py
Tick! The time is: 2019-08-22 23:23:00.001962
/root/homework/flask_test/flask_test/lib/python3.6/site-packages/setuptools/command/test.py
Tick! The time is: 2019-08-23 23:23:00.001760
/root/homework/flask_test/flask_test/lib/python3.6/site-packages/setuptools/command/test.py
Tick! The time is: 2019-08-24 23:23:00.002172
/root/homework/flask_test/flask_test/lib/python3.6/site-packages/setuptools/command/test.py
Tick! The time is: 2019-08-25 23:23:00.001980
/root/homework/flask_test/flask_test/lib/python3.6/site-packages/setuptools/command/test.py
Tick! The time is: 2019-08-26 23:23:00.001976
/root/homework/flask_test/flask_test/lib/python3.6/site-packages/setuptools/command/test.py
Tick! The time is: 2019-08-27 23:23:00.001921
/root/homework/flask_test/flask_test/lib/python3.6/site-packages/setuptools/command/test.py
Tick! The time is: 2019-08-28 23:23:00.002193
/root/homework/flask_test/flask_test/lib/python3.6/site-packages/setuptools/command/test.py
Tick! The time is: 2019-08-29 23:23:00.002182
/root/homework/flask_test/flask_test/lib/python3.6/site-packages/setuptools/command/test.py
Tick! The time is: 2019-08-30 23:23:00.002152
/root/homework/flask_test/flask_test/lib/python3.6/site-packages/setuptools/command/test.py
Tick! The time is: 2019-08-31 23:23:00.002455
/root/homework/flask_test/flask_test/lib/python3.6/site-packages/setuptools/command/test.py
Tick! The time is: 2019-09-01 23:23:00.001907
/root/homework/flask_test/flask_test/lib/python3.6/site-packages/setuptools/command/test.py
Tick! The time is: 2019-09-02 23:23:00.002112
/root/homework/flask_test/flask_test/lib/python3.6/site-packages/setuptools/command/test.py
Tick! The time is: 2019-09-03 23:23:00.002249
/root/homework/flask_test/flask_test/lib/python3.6/site-packages/setuptools/command/test.py
Tick! The time is: 2019-09-04 23:23:00.002151
/root/homework/flask_test/flask_test/lib/python3.6/site-packages/setuptools/command/test.py
Tick! The time is: 2019-09-05 23:23:00.002141
/root/homework/flask_test/flask_test/lib/python3.6/site-packages/setuptools/command/test.py
Tick! The time is: 2019-09-06 23:23:00.002021
/root/homework/flask_test/flask_test/lib/python3.6/site-packages/setuptools/command/test.py
Tick! The time is: 2019-09-07 23:23:00.002422
/root/homework/flask_test/flask_test/lib/python3.6/site-packages/setuptools/command/test.py
Tick! The time is: 2019-09-08 23:23:00.002201
/root/homework/flask_test/flask_test/lib/python3.6/site-packages/setuptools/command/test.py
Tick! The time is: 2019-09-09 23:23:00.002266
/root/homework/flask_test/flask_test/lib/python3.6/site-packages/setuptools/command/test.py
Tick! The time is: 2019-09-10 23:23:00.002345
/root/homework/flask_test/flask_test/lib/python3.6/site-packages/setuptools/command/test.py
Tick! The time is: 2019-09-11 23:23:00.002229
/root/homework/flask_test/flask_test/lib/python3.6/site-packages/setuptools/command/test.py
Tick! The time is: 2019-09-12 23:23:00.002154
/root/homework/flask_test/flask_test/lib/python3.6/site-packages/setuptools/command/test.py
Tick! The time is: 2019-09-13 23:23:00.002181
/root/homework/flask_test/flask_test/lib/python3.6/site-packages/setuptools/command/test.py
Tick! The time is: 2019-09-14 23:23:00.002399
/root/homework/flask_test/flask_test/lib/python3.6/site-packages/setuptools/command/test.py
Tick! The time is: 2019-09-15 23:23:00.002456To git@github.com:dajun928/Tool.git
   831d354..305b5d6  master -> master
Job "cut_single_file (trigger: cron[hour='23', minute='22'], next run at: 2019-09-17 23:22:00 CST)" raised an exception
Traceback (most recent call last):
  File "/root/anaconda3/lib/python3.6/site-packages/apscheduler/executors/base.py", line 125, in run_job
    retval = job.func(*job.args, **job.kwargs)
  File "control.py", line 56, in cut_single_file
    shutil.move(src_file, dsc_path)
  File "/root/anaconda3/lib/python3.6/shutil.py", line 542, in move
    raise Error("Destination path '%s' already exists" % real_dst)
shutil.Error: Destination path '/root/Projects/gitdemo/test/Tool/Tool/test.py' already exists
To git@github.com:dajun928/Tool.git
   305b5d6..028380c  master -> master
To git@github.com:dajun928/Tool.git
   028380c..50d8036  master -> master
Job "cut_single_file (trigger: cron[hour='23', minute='22'], next run at: 2019-09-19 23:22:00 CST)" raised an exception
Traceback (most recent call last):
  File "/root/anaconda3/lib/python3.6/site-packages/apscheduler/executors/base.py", line 125, in run_job
    retval = job.func(*job.args, **job.kwargs)
  File "control.py", line 56, in cut_single_file
    shutil.move(src_file, dsc_path)
  File "/root/anaconda3/lib/python3.6/shutil.py", line 542, in move
    raise Error("Destination path '%s' already exists" % real_dst)
shutil.Error: Destination path '/root/Projects/gitdemo/test/Tool/Tool/test.py' already exists
To git@github.com:dajun928/Tool.git
   50d8036..1ff10c3  master -> master
Job "cut_single_file (trigger: cron[hour='23', minute='22'], next run at: 2019-09-20 23:22:00 CST)" raised an exception
Traceback (most recent call last):
  File "/root/anaconda3/lib/python3.6/site-packages/apscheduler/executors/base.py", line 125, in run_job
    retval = job.func(*job.args, **job.kwargs)
  File "control.py", line 56, in cut_single_file
    shutil.move(src_file, dsc_path)
  File "/root/anaconda3/lib/python3.6/shutil.py", line 542, in move
    raise Error("Destination path '%s' already exists" % real_dst)
shutil.Error: Destination path '/root/Projects/gitdemo/test/Tool/Tool/test.py' already exists
To git@github.com:dajun928/Tool.git
   1ff10c3..740d13b  master -> master
Job "cut_single_file (trigger: cron[hour='23', minute='22'], next run at: 2019-09-21 23:22:00 CST)" raised an exception
Traceback (most recent call last):
  File "/root/anaconda3/lib/python3.6/site-packages/apscheduler/executors/base.py", line 125, in run_job
    retval = job.func(*job.args, **job.kwargs)
  File "control.py", line 56, in cut_single_file
    shutil.move(src_file, dsc_path)
  File "/root/anaconda3/lib/python3.6/shutil.py", line 542, in move
    raise Error("Destination path '%s' already exists" % real_dst)
shutil.Error: Destination path '/root/Projects/gitdemo/test/Tool/Tool/test.py' already exists
To git@github.com:dajun928/Tool.git
   740d13b..e1ede23  master -> master
Job "cut_single_file (trigger: cron[hour='23', minute='22'], next run at: 2019-09-22 23:22:00 CST)" raised an exception
Traceback (most recent call last):
  File "/root/anaconda3/lib/python3.6/site-packages/apscheduler/executors/base.py", line 125, in run_job
    retval = job.func(*job.args, **job.kwargs)
  File "control.py", line 56, in cut_single_file
    shutil.move(src_file, dsc_path)
  File "/root/anaconda3/lib/python3.6/shutil.py", line 542, in move
    raise Error("Destination path '%s' already exists" % real_dst)
shutil.Error: Destination path '/root/Projects/gitdemo/test/Tool/Tool/test.py' already exists
To git@github.com:dajun928/Tool.git
   e1ede23..30296b0  master -> master
Job "cut_single_file (trigger: cron[hour='23', minute='22'], next run at: 2019-09-23 23:22:00 CST)" raised an exception
Traceback (most recent call last):
  File "/root/anaconda3/lib/python3.6/site-packages/apscheduler/executors/base.py", line 125, in run_job
    retval = job.func(*job.args, **job.kwargs)
  File "control.py", line 56, in cut_single_file
    shutil.move(src_file, dsc_path)
  File "/root/anaconda3/lib/python3.6/shutil.py", line 542, in move
    raise Error("Destination path '%s' already exists" % real_dst)
shutil.Error: Destination path '/root/Projects/gitdemo/test/Tool/Tool/test.py' already exists
To git@github.com:dajun928/Tool.git
   30296b0..1203dc1  master -> master
Job "cut_single_file (trigger: cron[hour='23', minute='22'], next run at: 2019-09-24 23:22:00 CST)" raised an exception
Traceback (most recent call last):
  File "/root/anaconda3/lib/python3.6/site-packages/apscheduler/executors/base.py", line 125, in run_job
    retval = job.func(*job.args, **job.kwargs)
  File "control.py", line 56, in cut_single_file
    shutil.move(src_file, dsc_path)
  File "/root/anaconda3/lib/python3.6/shutil.py", line 542, in move
    raise Error("Destination path '%s' already exists" % real_dst)
shutil.Error: Destination path '/root/Projects/gitdemo/test/Tool/Tool/test.py' already exists
To git@github.com:dajun928/Tool.git
   1203dc1..25e205e  master -> master
Job "cut_single_file (trigger: cron[hour='23', minute='22'], next run at: 2019-09-25 23:22:00 CST)" raised an exception
Traceback (most recent call last):
  File "/root/anaconda3/lib/python3.6/site-packages/apscheduler/executors/base.py", line 125, in run_job
    retval = job.func(*job.args, **job.kwargs)
  File "control.py", line 56, in cut_single_file
    shutil.move(src_file, dsc_path)
  File "/root/anaconda3/lib/python3.6/shutil.py", line 542, in move
    raise Error("Destination path '%s' already exists" % real_dst)
shutil.Error: Destination path '/root/Projects/gitdemo/test/Tool/Tool/test.py' already exists
To git@github.com:dajun928/Tool.git
   25e205e..6552eec  master -> master
Job "cut_single_file (trigger: cron[hour='23', minute='22'], next run at: 2019-09-26 23:22:00 CST)" raised an exception
Traceback (most recent call last):
  File "/root/anaconda3/lib/python3.6/site-packages/apscheduler/executors/base.py", line 125, in run_job
    retval = job.func(*job.args, **job.kwargs)
  File "control.py", line 56, in cut_single_file
    shutil.move(src_file, dsc_path)
  File "/root/anaconda3/lib/python3.6/shutil.py", line 542, in move
    raise Error("Destination path '%s' already exists" % real_dst)
shutil.Error: Destination path '/root/Projects/gitdemo/test/Tool/Tool/test.py' already exists
To git@github.com:dajun928/Tool.git
   6552eec..211339c  master -> master
Job "cut_single_file (trigger: cron[hour='23', minute='22'], next run at: 2019-09-27 23:22:00 CST)" raised an exception
Traceback (most recent call last):
  File "/root/anaconda3/lib/python3.6/site-packages/apscheduler/executors/base.py", line 125, in run_job
    retval = job.func(*job.args, **job.kwargs)
  File "control.py", line 56, in cut_single_file
    shutil.move(src_file, dsc_path)
  File "/root/anaconda3/lib/python3.6/shutil.py", line 542, in move
    raise Error("Destination path '%s' already exists" % real_dst)
shutil.Error: Destination path '/root/Projects/gitdemo/test/Tool/Tool/test.py' already exists
To git@github.com:dajun928/Tool.git
   211339c..a90e1ec  master -> master
Job "cut_single_file (trigger: cron[hour='23', minute='22'], next run at: 2019-09-28 23:22:00 CST)" raised an exception
Traceback (most recent call last):
  File "/root/anaconda3/lib/python3.6/site-packages/apscheduler/executors/base.py", line 125, in run_job
    retval = job.func(*job.args, **job.kwargs)
  File "control.py", line 56, in cut_single_file
    shutil.move(src_file, dsc_path)
  File "/root/anaconda3/lib/python3.6/shutil.py", line 542, in move
    raise Error("Destination path '%s' already exists" % real_dst)
shutil.Error: Destination path '/root/Projects/gitdemo/test/Tool/Tool/test.py' already exists
To git@github.com:dajun928/Tool.git
   a90e1ec..1756b74  master -> master
Job "cut_single_file (trigger: cron[hour='23', minute='22'], next run at: 2019-09-29 23:22:00 CST)" raised an exception
Traceback (most recent call last):
  File "/root/anaconda3/lib/python3.6/site-packages/apscheduler/executors/base.py", line 125, in run_job
    retval = job.func(*job.args, **job.kwargs)
  File "control.py", line 56, in cut_single_file
    shutil.move(src_file, dsc_path)
  File "/root/anaconda3/lib/python3.6/shutil.py", line 542, in move
    raise Error("Destination path '%s' already exists" % real_dst)
shutil.Error: Destination path '/root/Projects/gitdemo/test/Tool/Tool/test.py' already exists
To git@github.com:dajun928/Tool.git
   1756b74..d71f2b3  master -> master
Job "cut_single_file (trigger: cron[hour='23', minute='22'], next run at: 2019-09-30 23:22:00 CST)" raised an exception
Traceback (most recent call last):
  File "/root/anaconda3/lib/python3.6/site-packages/apscheduler/executors/base.py", line 125, in run_job
    retval = job.func(*job.args, **job.kwargs)
  File "control.py", line 56, in cut_single_file
    shutil.move(src_file, dsc_path)
  File "/root/anaconda3/lib/python3.6/shutil.py", line 542, in move
    raise Error("Destination path '%s' already exists" % real_dst)
shutil.Error: Destination path '/root/Projects/gitdemo/test/Tool/Tool/test.py' already exists
To git@github.com:dajun928/Tool.git
   d71f2b3..0000265  master -> master
Job "cut_single_file (trigger: cron[hour='23', minute='22'], next run at: 2019-10-01 23:22:00 CST)" raised an exception
Traceback (most recent call last):
  File "/root/anaconda3/lib/python3.6/site-packages/apscheduler/executors/base.py", line 125, in run_job
    retval = job.func(*job.args, **job.kwargs)
  File "control.py", line 56, in cut_single_file
    shutil.move(src_file, dsc_path)
  File "/root/anaconda3/lib/python3.6/shutil.py", line 542, in move
    raise Error("Destination path '%s' already exists" % real_dst)
shutil.Error: Destination path '/root/Projects/gitdemo/test/Tool/Tool/test.py' already exists
To git@github.com:dajun928/Tool.git
   0000265..d8cd54d  master -> master
Job "cut_single_file (trigger: cron[hour='23', minute='22'], next run at: 2019-10-02 23:22:00 CST)" raised an exception
Traceback (most recent call last):
  File "/root/anaconda3/lib/python3.6/site-packages/apscheduler/executors/base.py", line 125, in run_job
    retval = job.func(*job.args, **job.kwargs)
  File "control.py", line 56, in cut_single_file
    shutil.move(src_file, dsc_path)
  File "/root/anaconda3/lib/python3.6/shutil.py", line 542, in move
    raise Error("Destination path '%s' already exists" % real_dst)
shutil.Error: Destination path '/root/Projects/gitdemo/test/Tool/Tool/test.py' already exists
To git@github.com:dajun928/Tool.git
   d8cd54d..fbe58bb  master -> master
Job "cut_single_file (trigger: cron[hour='23', minute='22'], next run at: 2019-10-03 23:22:00 CST)" raised an exception
Traceback (most recent call last):
  File "/root/anaconda3/lib/python3.6/site-packages/apscheduler/executors/base.py", line 125, in run_job
    retval = job.func(*job.args, **job.kwargs)
  File "control.py", line 56, in cut_single_file
    shutil.move(src_file, dsc_path)
  File "/root/anaconda3/lib/python3.6/shutil.py", line 542, in move
    raise Error("Destination path '%s' already exists" % real_dst)
shutil.Error: Destination path '/root/Projects/gitdemo/test/Tool/Tool/test.py' already exists
To git@github.com:dajun928/Tool.git
   fbe58bb..a4ab2b9  master -> master
Job "cut_single_file (trigger: cron[hour='23', minute='22'], next run at: 2019-10-04 23:22:00 CST)" raised an exception
Traceback (most recent call last):
  File "/root/anaconda3/lib/python3.6/site-packages/apscheduler/executors/base.py", line 125, in run_job
    retval = job.func(*job.args, **job.kwargs)
  File "control.py", line 56, in cut_single_file
    shutil.move(src_file, dsc_path)
  File "/root/anaconda3/lib/python3.6/shutil.py", line 542, in move
    raise Error("Destination path '%s' already exists" % real_dst)
shutil.Error: Destination path '/root/Projects/gitdemo/test/Tool/Tool/test.py' already exists
To git@github.com:dajun928/Tool.git
   a4ab2b9..b13e23b  master -> master
Job "cut_single_file (trigger: cron[hour='23', minute='22'], next run at: 2019-10-05 23:22:00 CST)" raised an exception
Traceback (most recent call last):
  File "/root/anaconda3/lib/python3.6/site-packages/apscheduler/executors/base.py", line 125, in run_job
    retval = job.func(*job.args, **job.kwargs)
  File "control.py", line 56, in cut_single_file
    shutil.move(src_file, dsc_path)
  File "/root/anaconda3/lib/python3.6/shutil.py", line 542, in move
    raise Error("Destination path '%s' already exists" % real_dst)
shutil.Error: Destination path '/root/Projects/gitdemo/test/Tool/Tool/test.py' already exists
To git@github.com:dajun928/Tool.git
   b13e23b..47af505  master -> master
Job "cut_single_file (trigger: cron[hour='23', minute='22'], next run at: 2019-10-06 23:22:00 CST)" raised an exception
Traceback (most recent call last):
  File "/root/anaconda3/lib/python3.6/site-packages/apscheduler/executors/base.py", line 125, in run_job
    retval = job.func(*job.args, **job.kwargs)
  File "control.py", line 56, in cut_single_file
    shutil.move(src_file, dsc_path)
  File "/root/anaconda3/lib/python3.6/shutil.py", line 542, in move
    raise Error("Destination path '%s' already exists" % real_dst)
shutil.Error: Destination path '/root/Projects/gitdemo/test/Tool/Tool/test.py' already exists
To git@github.com:dajun928/Tool.git
   47af505..22de5c0  master -> master
Job "cut_single_file (trigger: cron[hour='23', minute='22'], next run at: 2019-10-07 23:22:00 CST)" raised an exception
Traceback (most recent call last):
  File "/root/anaconda3/lib/python3.6/site-packages/apscheduler/executors/base.py", line 125, in run_job
    retval = job.func(*job.args, **job.kwargs)
  File "control.py", line 56, in cut_single_file
    shutil.move(src_file, dsc_path)
  File "/root/anaconda3/lib/python3.6/shutil.py", line 542, in move
    raise Error("Destination path '%s' already exists" % real_dst)
shutil.Error: Destination path '/root/Projects/gitdemo/test/Tool/Tool/test.py' already exists
To git@github.com:dajun928/Tool.git
   22de5c0..c023787  master -> master
Job "cut_single_file (trigger: cron[hour='23', minute='22'], next run at: 2019-10-08 23:22:00 CST)" raised an exception
Traceback (most recent call last):
  File "/root/anaconda3/lib/python3.6/site-packages/apscheduler/executors/base.py", line 125, in run_job
    retval = job.func(*job.args, **job.kwargs)
  File "control.py", line 56, in cut_single_file
    shutil.move(src_file, dsc_path)
  File "/root/anaconda3/lib/python3.6/shutil.py", line 542, in move
    raise Error("Destination path '%s' already exists" % real_dst)
shutil.Error: Destination path '/root/Projects/gitdemo/test/Tool/Tool/test.py' already exists
To git@github.com:dajun928/Tool.git
   c023787..4fe79c2  master -> master
Job "cut_single_file (trigger: cron[hour='23', minute='22'], next run at: 2019-10-09 23:22:00 CST)" raised an exception
Traceback (most recent call last):
  File "/root/anaconda3/lib/python3.6/site-packages/apscheduler/executors/base.py", line 125, in run_job
    retval = job.func(*job.args, **job.kwargs)
  File "control.py", line 56, in cut_single_file
    shutil.move(src_file, dsc_path)
  File "/root/anaconda3/lib/python3.6/shutil.py", line 542, in move
    raise Error("Destination path '%s' already exists" % real_dst)
shutil.Error: Destination path '/root/Projects/gitdemo/test/Tool/Tool/test.py' already exists
To git@github.com:dajun928/Tool.git
   4fe79c2..47e50b5  master -> master
Job "cut_single_file (trigger: cron[hour='23', minute='22'], next run at: 2019-10-10 23:22:00 CST)" raised an exception
Traceback (most recent call last):
  File "/root/anaconda3/lib/python3.6/site-packages/apscheduler/executors/base.py", line 125, in run_job
    retval = job.func(*job.args, **job.kwargs)
  File "control.py", line 56, in cut_single_file
    shutil.move(src_file, dsc_path)
  File "/root/anaconda3/lib/python3.6/shutil.py", line 542, in move
    raise Error("Destination path '%s' already exists" % real_dst)
shutil.Error: Destination path '/root/Projects/gitdemo/test/Tool/Tool/test.py' already exists
To git@github.com:dajun928/Tool.git
   47e50b5..90f251a  master -> master
Job "cut_single_file (trigger: cron[hour='23', minute='22'], next run at: 2019-10-11 23:22:00 CST)" raised an exception
Traceback (most recent call last):
  File "/root/anaconda3/lib/python3.6/site-packages/apscheduler/executors/base.py", line 125, in run_job
    retval = job.func(*job.args, **job.kwargs)
  File "control.py", line 56, in cut_single_file
    shutil.move(src_file, dsc_path)
  File "/root/anaconda3/lib/python3.6/shutil.py", line 542, in move
    raise Error("Destination path '%s' already exists" % real_dst)
shutil.Error: Destination path '/root/Projects/gitdemo/test/Tool/Tool/test.py' already exists
To git@github.com:dajun928/Tool.git
   90f251a..fcbd8cc  master -> master
Job "cut_single_file (trigger: cron[hour='23', minute='22'], next run at: 2019-10-12 23:22:00 CST)" raised an exception
Traceback (most recent call last):
  File "/root/anaconda3/lib/python3.6/site-packages/apscheduler/executors/base.py", line 125, in run_job
    retval = job.func(*job.args, **job.kwargs)
  File "control.py", line 56, in cut_single_file
    shutil.move(src_file, dsc_path)
  File "/root/anaconda3/lib/python3.6/shutil.py", line 542, in move
    raise Error("Destination path '%s' already exists" % real_dst)
shutil.Error: Destination path '/root/Projects/gitdemo/test/Tool/Tool/test.py' already exists
To git@github.com:dajun928/Tool.git
   fcbd8cc..d6e89fc  master -> master
Job "cut_single_file (trigger: cron[hour='23', minute='22'], next run at: 2019-10-13 23:22:00 CST)" raised an exception
Traceback (most recent call last):
  File "/root/anaconda3/lib/python3.6/site-packages/apscheduler/executors/base.py", line 125, in run_job
    retval = job.func(*job.args, **job.kwargs)
  File "control.py", line 56, in cut_single_file
    shutil.move(src_file, dsc_path)
  File "/root/anaconda3/lib/python3.6/shutil.py", line 542, in move
    raise Error("Destination path '%s' already exists" % real_dst)
shutil.Error: Destination path '/root/Projects/gitdemo/test/Tool/Tool/test.py' already exists
To git@github.com:dajun928/Tool.git
   d6e89fc..7cc7f5d  master -> master
Job "cut_single_file (trigger: cron[hour='23', minute='22'], next run at: 2019-10-14 23:22:00 CST)" raised an exception
Traceback (most recent call last):
  File "/root/anaconda3/lib/python3.6/site-packages/apscheduler/executors/base.py", line 125, in run_job
    retval = job.func(*job.args, **job.kwargs)
  File "control.py", line 56, in cut_single_file
    shutil.move(src_file, dsc_path)
  File "/root/anaconda3/lib/python3.6/shutil.py", line 542, in move
    raise Error("Destination path '%s' already exists" % real_dst)
shutil.Error: Destination path '/root/Projects/gitdemo/test/Tool/Tool/test.py' already exists
To git@github.com:dajun928/Tool.git
   7cc7f5d..f94a05a  master -> master
Job "cut_single_file (trigger: cron[hour='23', minute='22'], next run at: 2019-10-15 23:22:00 CST)" raised an exception
Traceback (most recent call last):
  File "/root/anaconda3/lib/python3.6/site-packages/apscheduler/executors/base.py", line 125, in run_job
    retval = job.func(*job.args, **job.kwargs)
  File "control.py", line 56, in cut_single_file
    shutil.move(src_file, dsc_path)
  File "/root/anaconda3/lib/python3.6/shutil.py", line 542, in move
    raise Error("Destination path '%s' already exists" % real_dst)
shutil.Error: Destination path '/root/Projects/gitdemo/test/Tool/Tool/test.py' already exists
